Workbook

Sheet تعليمات
A1: دليل الاستخدام — قياس نضج النموذج التشغيلي
A3: ١. عبّئ عمود «نسبة التحقق %» فقط (الخلايا الصفراء) لكل عنصر، من ٠ إلى ١٠٠. القيم الحالية وهمية للتجربة.
A4: ٢. «الوزن المكتسب» = الوزن × نسبة التحقق ÷ ١٠٠، يُحسب تلقائيًا، ودرجة المرحلة وتصنيفها في ورقة «النتائج».
A5: ٣. الهيكل في هذا الملف: القطاع العسكري والقطاع الصحي يُقاس كلٌّ على مستوى القطاع (عمود الوحدة = اسم القطاع، والوكالة = —).
A6: ٤. القطاع التنفيذي: «وكالة (أ)» تنقسم لـ٧ وحدات، «وكالة (ب)» لـ٣ وحدات، والوكالات (ج) و(د) و(هـ) و(و) تُقاس على مستوى الوكالة (الوحدة = اسم الوكالة).
A7: ٥. كل وحدة/وكالة/قطاع مقاس يأخذ ١٨ صفًا (التصميم ٦ + التفعيل ٧ + التشغيل ٥).
A8: ٦. لإضافة كيان جديد: انسخ ١٨ صفًا كاملة وغيّر القطاع/الوكالة/الوحدة، وأضف ٣ صفوف مقابلة في «النتائج».
A9: ٧. الأوزان وحدود التصنيف في ورقة «المرجع» — أي تعديل ينعكس تلقائيًا.
A10: ٨. ورقة «الإدخال والحساب» مسطّحة وجاهزة كمصدر مباشر لـ Power BI.

Sheet الإدخال والحساب
A1: ID | B1: القطاع | C1: الوحدة التنظيمية الرئيسية | D1: الوحدة التنظيمية الفرعية | E1: المرحلة | F1: العنصر | G1: الوزن في المرحلة | H1: نسبة التحقق % | I1: الوزن المكتسب
A2: M01 | B2: القطاع العسكري | C2: القطاع العسكري | D2: العسكرية | E2: مرحلة التصميم | F2: الدور | G2: =SUMIFS(المرجع!$C$2:$C$19,المرجع!$A$2:$A$19,$E2,المرجع!$B$2:$B$19,$F2) -> 25 | H2: 98 | I2: =G2*H2/100 -> 24.5
A3: M02 | B3: القطاع العسكري | C3: القطاع العسكري | D3: العسكرية | E3: مرحلة التصميم | F3: الأهداف ومؤشرات الأداء | G3: =SUMIFS(المرجع!$C$2:$C$19,المرجع!$A$2:$A$19,$E3,المرجع!$B$2:$B$19,$F3) -> 15 | H3: 81 | I3: =G3*H3/100 -> 12.15
A4: M03 | B4: القطاع العسكري | C4: القطاع العسكري | D4: العسكرية | E4: مرحلة التصميم | F4: الحوكمة | G4: =SUMIFS(المرجع!$C$2:$C$19,المرجع!$A$2:$A$19,$E4,المرجع!$B$2:$B$19,$F4) -> 15 | H4: 78 | I4: =G4*H4/100 -> 11.7
A5: M04 | B5: القطاع العسكري | C5: القطاع العسكري | D5: العسكرية | E5: مرحلة التصميم | F5: التنظيم | G5: =SUMIFS(المرجع!$C$2:$C$19,المرجع!$A$2:$A$19,$E5,المرجع!$B$2:$B$19,$F5) -> 20 | H5: 86 | I5: =G5*H5/100 -> 17.2
A6: M05 | B6: القطاع العسكري | C6: القطاع العسكري | D6: العسكرية | E6: مرحلة التصميم | F6: الموارد | G6: =SUMIFS(المرجع!$C$2:$C$19,المرجع!$A$2:$A$19,$E6,المرجع!$B$2:$B$19,$F6) -> 20 | H6: 85 | I6: =G6*H6/100 -> 17
A7: M06 | B7: القطاع العسكري | C7: القطاع العسكري | D7: العسكرية | E7: مرحلة التصميم | F7: الإجراءات | G7: =SUMIFS(المرجع!$C$2:$C$19,المرجع!$A$2:$A$19,$E7,المرجع!$B$2:$B$19,$F7) -> 5 | H7: 85 | I7: =G7*H7/100 -> 4.25
A8: M07 | B8: القطاع العسكري | C8: القطاع العسكري | D8: العسكرية | E8: التفعيل | F8: الدور | G8: =SUMIFS(المرجع!$C$2:$C$19,المرجع!$A$2:$A$19,$E8,المرجع!$B$2:$B$19,$F8) -> 15 | H8: 53 | I8: =G8*H8/100 -> 7.95
A9: M08 | B9: القطاع العسكري | C9: القطاع العسكري | D9: العسكرية | E9: التفعيل | F9: الأهداف ومؤشرات الأداء | G9: =SUMIFS(المرجع!$C$2:$C$19,المرجع!$A$2:$A$19,$E9,المرجع!$B$2:$B$19,$F9) -> 15 | H9: 51 | I9: =G9*H9/100 -> 7.65
A10: M09 | B10: القطاع العسكري | C10: القطاع العسكري | D10: العسكرية | E10: التفعيل | F10: الحوكمة | G10: =SUMIFS(المرجع!$C$2:$C$19,المرجع!$A$2:$A$19,$E10,المرجع!$B$2:$B$19,$F10) -> 15 | H10: 79 | I10: =G10*H10/100 -> 11.85
A11: M10 | B11: القطاع العسكري | C11: القطاع العسكري | D11: العسكرية | E11: التفعيل | F11: التنظيم | G11: =SUMIFS(المرجع!$C$2:$C$19,المرجع!$A$2:$A$19,$E11,المرجع!$B$2:$B$19,$F11) -> 20 | H11: 50 | I11: =G11*H11/100 -> 10
A12: M11 | B12: القطاع العسكري | C12: القطاع العسكري | D12: العسكرية | E12: التفعيل | F12: الموارد | G12: =SUMIFS(المرجع!$C$2:$C$19,المرجع!$A$2:$A$19,$E12,المرجع!$B$2:$B$19,$F12) -> 25 | H12: 82 | I12: =G12*H12/100 -> 20.5
A13: M12 | B13: القطاع العسكري | C13: القطاع العسكري | D13: العسكرية | E13: التفعيل | F13: الإجراءات | G13: =SUMIFS(المرجع!$C$2:$C$19,المرجع!$A$2:$A$19,$E13,المرجع!$B$2:$B$19,$F13) -> 5 | H13: 72 | I13: =G13*H13/100 -> 3.6
... A38: E01 | B38: القطاع التنفيذي | C38: وكالة (أ) | D38: وحدة أ-١ | E38: مرحلة التصميم | F38: الدور | G38: =SUMIFS(المرجع!$C$2:$C$19,المرجع!$A$2:$A$19,$E38,المرجع!$B$2:$B$19,$F38) -> 25 | H38: 74.7 | I38: =G38*H38/100 -> 18.675
A39: E02 | B39: القطاع التنفيذي | C39: وكالة (أ) | D39: وحدة أ-١ | E39: مرحلة التصميم | F39: الأهداف ومؤشرات الأداء | G39: =SUMIFS(المرجع!$C$2:$C$19,المرجع!$A$2:$A$19,$E39,المرجع!$B$2:$B$19,$F39) -> 15 | H39: =89.99 -> 89.99 | I39: =G39*H39/100 -> 13.4985
A40: E03 | B40: القطاع التنفيذي | C40: وكالة (أ) | D40: وحدة أ-١ | E40: مرحلة التصميم | F40: الحوكمة | G40: =SUMIFS(المرجع!$C$2:$C$19,المرجع!$A$2:$A$19,$E40,المرجع!$B$2:$B$19,$F40) -> 15 | H40: =89.99 -> 89.99 | I40: =G40*H40/100 -> 13.4985
A41: E04 | B41: القطاع التنفيذي | C41: وكالة (أ) | D41: وحدة أ-١ | E41: مرحلة التصميم | F41: التنظيم | G41: =SUMIFS(المرجع!$C$2:$C$19,المرجع!$A$2:$A$19,$E41,المرجع!$B$2:$B$19,$F41) -> 20 | H41: =89.99 -> 89.99 | I41: =G41*H41/100 -> 17.998
A42: E05 | B42: القطاع التنفيذي | C42: وكالة (أ) | D42: وحدة أ-١ | E42: مرحلة التصميم | F42: الموارد | G42: =SUMIFS(المرجع!$C$2:$C$19,المرجع!$A$2:$A$19,$E42,المرجع!$B$2:$B$19,$F42) -> 20 | H42: =89.99 -> 89.99 | I42: =G42*H42/100 -> 17.998
A43: E06 | B43: القطاع التنفيذي | C43: وكالة (أ) | D43: وحدة أ-١ | E43: مرحلة التصميم | F43: الإجراءات | G43: =SUMIFS(المرجع!$C$2:$C$19,المرجع!$A$2:$A$19,$E43,المرجع!$B$2:$B$19,$F43) -> 5 | H43: =89.99 -> 89.99 | I43: =G43*H43/100 -> 4.4995
A44: E07 | B44: القطاع التنفيذي | C44: وكالة (أ) | D44: وحدة أ-١ | E44: التفعيل | F44: الدور | G44: =SUMIFS(المرجع!$C$2:$C$19,المرجع!$A$2:$A$19,$E44,المرجع!$B$2:$B$19,$F44) -> 15 | H44: 67 | I44: =G44*H44/100 -> 10.05
A45: E08 | B45: القطاع التنفيذي | C45: وكالة (أ) | D45: وحدة أ-١ | E45: التفعيل | F45: الأهداف ومؤشرات الأداء | G45: =SUMIFS(المرجع!$C$2:$C$19,المرجع!$A$2:$A$19,$E45,المرجع!$B$2:$B$19,$F45) -> 15 | H45: 61 | I45: =G45*H45/100 -> 9.15
A46: E09 | B46: القطاع التنفيذي | C46: وكالة (أ) | D46: وحدة أ-١ | E46: التفعيل | F46: الحوكمة | G46: =SUMIFS(المرجع!$C$2:$C$19,المرجع!$A$2:$A$19,$E46,المرجع!$B$2:$B$19,$F46) -> 15 | H46: 47 | I46: =G46*H46/100 -> 7.05
A47: E10 | B47: القطاع التنفيذي | C47: وكالة (أ) | D47: وحدة أ-١ | E47: التفعيل | F47: التنظيم | G47: =SUMIFS(المرجع!$C$2:$C$19,المرجع!$A$2:$A$19,$E47,المرجع!$B$2:$B$19,$F47) -> 20 | H47: 74 | I47: =G47*H47/100 -> 14.8
A48: E11 | B48: القطاع التنفيذي | C48: وكالة (أ) | D48: وحدة أ-١ | E48: التفعيل | F48: الموارد | G48: =SUMIFS(المرجع!$C$2:$C$19,المرجع!$A$2:$A$19,$E48,المرجع!$B$2:$B$19,$F48) -> 25 | H48: 79 | I48: =G48*H48/100 -> 19.75
A49: E12 | B49: القطاع التنفيذي | C49: وكالة (أ) | D49: وحدة أ-١ | E49: التفعيل | F49: الإجراءات | G49: =SUMIFS(المرجع!$C$2:$C$19,المرجع!$A$2:$A$19,$E49,المرجع!$B$2:$B$19,$F49) -> 5 | H49: 52 | I49: =G49*H49/100 -> 2.6
A50: E13 | B50: القطاع التنفيذي | C50: وكالة (أ) | D50: وحدة أ-١ | E50: التفعيل | F50: إنتاج المخرج الأول | G50: =SUMIFS(المرجع!$C$2:$C$19,المرجع!$A$2:$A$19,$E50,المرجع!$B$2:$B$19,$F50) -> 5 | H50: 69 | I50: =G50*H50/100 -> 3.45
A51: E14 | B51: القطاع التنفيذي | C51: وكالة (أ) | D51: وحدة أ-١ | E51: مرحلة التشغيل | F51: الأهداف ومؤشرات الأداء | G51: =SUMIFS(المرجع!$C$2:$C$19,المرجع!$A$2:$A$19,$E51,المرجع!$B$2:$B$19,$F51) -> 25 | H51: 29 | I51: =G51*H51/100 -> 7.25
A52: E15 | B52: القطاع التنفيذي | C52: وكالة (أ) | D52: وحدة أ-١ | E52: مرحلة التشغيل | F52: الحوكمة | G52: =SUMIFS(المرجع!$C$2:$C$19,المرجع!$A$2:$A$19,$E52,المرجع!$B$2:$B$19,$F52) -> 15 | H52: 59 | I52: =G52*H52/100 -> 8.85
A53: E16 | B53: القطاع التنفيذي | C53: وكالة (أ) | D53: وحدة أ-١ | E53: مرحلة التشغيل | F53: الموارد | G53: =SUMIFS(المرجع!$C$2:$C$19,المرجع!$A$2:$A$19,$E53,المرجع!$B$2:$B$19,$F53) -> 15 | H53: 42 | I53: =G53*H53/100 -> 6.3
A54: E17 | B54: القطاع التنفيذي | C54: وكالة (أ) | D54: وحدة أ-١ | E54: مرحلة التشغيل | F54: الإجراءات | G54: =SUMIFS(المرجع!$C$2:$C$19,المرجع!$A$2:$A$19,$E54,المرجع!$B$2:$B$19,$F54) -> 15 | H54: 64 | I54: =G54*H54/100 -> 9.6
A55: E18 | B55: القطاع التنفيذي | C55: وكالة (أ) | D55: وحدة أ-١ | E55: مرحلة التشغيل | F55: اكتمال المخرجات المستهدفة | G55: =SUMIFS(المرجع!$C$2:$C$19,المرجع!$A$2:$A$19,$E55,المرجع!$B$2:$B$19,$F55) -> 30 | H55: 63 | I55: =G55*H55/100 -> 18.9
A56: E19 | B56: القطاع التنفيذي | C56: وكالة (أ) | D56: وحدة أ-٢ | E56: مرحلة التصميم | F56: الدور | G56: =SUMIFS(المرجع!$C$2:$C$19,المرجع!$A$2:$A$19,$E56,المرجع!$B$2:$B$19,$F56) -> 25 | H56: =25.93 -> 25.93 | I56: =G56*H56/100 -> 6.4825
A57: E20 | B57: القطاع التنفيذي | C57: وكالة (أ) | D57: وحدة أ-٢ | E57: مرحلة التصميم | F57: الأهداف ومؤشرات الأداء | G57: =SUMIFS(المرجع!$C$2:$C$19,المرجع!$A$2:$A$19,$E57,المرجع!$B$2:$B$19,$F57) -> 15 | H57: =25.93 -> 25.93 | I57: =G57*H57/100 -> 3.8895
A58: E21 | B58: القطاع التنفيذي | C58: وكالة (أ) | D58: وحدة أ-٢ | E58: مرحلة التصميم | F58: الحوكمة | G58: =SUMIFS(المرجع!$C$2:$C$19,المرجع!$A$2:$A$19,$E58,المرجع!$B$2:$B$19,$F58) -> 15 | H58: =25.93 -> 25.93 | I58: =G58*H58/100 -> 3.8895
A59: E22 | B59: القطاع التنفيذي | C59: وكالة (أ) | D59: وحدة أ-٢ | E59: مرحلة التصميم | F59: التنظيم | G59: =SUMIFS(المرجع!$C$2:$C$19,المرجع!$A$2:$A$19,$E59,المرجع!$B$2:$B$19,$F59) -> 20 | H59: =25.93 -> 25.93 | I59: =G59*H59/100 -> 5.186
A60: E23 | B60: القطاع التنفيذي | C60: وكالة (أ) | D60: وحدة أ-٢ | E60: مرحلة التصميم | F60: الموارد | G60: =SUMIFS(المرجع!$C$2:$C$19,المرجع!$A$2:$A$19,$E60,المرجع!$B$2:$B$19,$F60) -> 20 | H60: =25.93 -> 25.93 | I60: =G60*H60/100 -> 5.186
A61: E24 | B61: القطاع التنفيذي | C61: وكالة (أ) | D61: وحدة أ-٢ | E61: مرحلة التصميم | F61: الإجراءات | G61: =SUMIFS(المرجع!$C$2:$C$19,المرجع!$A$2:$A$19,$E61,المرجع!$B$2:$B$19,$F61) -> 5 | H61: =25.93 -> 25.93 | I61: =G61*H61/100 -> 1.2965
A62: E25 | B62: القطاع التنفيذي | C62: وكالة (أ) | D62: وحدة أ-٢ | E62: التفعيل | F62: الدور | G62: =SUMIFS(المرجع!$C$2:$C$19,المرجع!$A$2:$A$19,$E62,المرجع!$B$2:$B$19,$F62) -> 15 | H62: 63 | I62: =G62*H62/100 -> 9.45
A63: E26 | B63: القطاع التنفيذي | C63: وكالة (أ) | D63: وحدة أ-٢ | E63: التفعيل | F63: الأهداف ومؤشرات الأداء | G63: =SUMIFS(المرجع!$C$2:$C$19,المرجع!$A$2:$A$19,$E63,المرجع!$B$2:$B$19,$F63) -> 15 | H63: 50 | I63: =G63*H63/100 -> 7.5
A64: E27 | B64: القطاع التنفيذي | C64: وكالة (أ) | D64: وحدة أ-٢ | E64: التفعيل | F64: الحوكمة | G64: =SUMIFS(المرجع!$C$2:$C$19,المرجع!$A$2:$A$19,$E64,المرجع!$B$2:$B$19,$F64) -> 15 | H64: 59 | I64: =G64*H64/100 -> 8.85
...

Sheet النتائج
A1: القطاع | B1: الوكالة | C1: الوحدة المقاسة | D1: المرحلة | E1: درجة المرحلة | F1: التصنيف
A2: القطاع العسكري | B2: — | C2: القطاع العسكري | D2: مرحلة التصميم | E2: =SUMIFS('الإدخال والحساب'!$I$2:$I$289,'الإدخال والحساب'!$D$2:$D$289,$C2,'الإدخال والحساب'!$E$2:$E$289,$D2) -> 0 | F2: =IF(E2>المرجع!$F$3,"متقدم",IF(E2<=المرجع!$F$2,"أولي","جزئي")) -> أولي
A3: القطاع العسكري | B3: — | C3: القطاع العسكري | D3: التفعيل | E3: =SUMIFS('الإدخال والحساب'!$I$2:$I$289,'الإدخال والحساب'!$D$2:$D$289,$C3,'الإدخال والحساب'!$E$2:$E$289,$D3) -> 0 | F3: =IF(E3>المرجع!$F$3,"متقدم",IF(E3<=المرجع!$F$2,"أولي","جزئي")) -> أولي
A4: القطاع العسكري | B4: — | C4: القطاع العسكري | D4: مرحلة التشغيل | E4: =SUMIFS('الإدخال والحساب'!$I$2:$I$289,'الإدخال والحساب'!$D$2:$D$289,$C4,'الإدخال والحساب'!$E$2:$E$289,$D4) -> 0 | F4: =IF(E4>المرجع!$F$3,"متقدم",IF(E4<=المرجع!$F$2,"أولي","جزئي")) -> أولي
A5: القطاع الصحي | B5: — | C5: القطاع الصحي | D5: مرحلة التصميم | E5: =SUMIFS('الإدخال والحساب'!$I$2:$I$289,'الإدخال والحساب'!$D$2:$D$289,$C5,'الإدخال والحساب'!$E$2:$E$289,$D5) -> 0 | F5: =IF(E5>المرجع!$F$3,"متقدم",IF(E5<=المرجع!$F$2,"أولي","جزئي")) -> أولي
A6: القطاع الصحي | B6: — | C6: القطاع الصحي | D6: التفعيل | E6: =SUMIFS('الإدخال والحساب'!$I$2:$I$289,'الإدخال والحساب'!$D$2:$D$289,$C6,'الإدخال والحساب'!$E$2:$E$289,$D6) -> 0 | F6: =IF(E6>المرجع!$F$3,"متقدم",IF(E6<=المرجع!$F$2,"أولي","جزئي")) -> أولي
A7: القطاع الصحي | B7: — | C7: القطاع الصحي | D7: مرحلة التشغيل | E7: =SUMIFS('الإدخال والحساب'!$I$2:$I$289,'الإدخال والحساب'!$D$2:$D$289,$C7,'الإدخال والحساب'!$E$2:$E$289,$D7) -> 0 | F7: =IF(E7>المرجع!$F$3,"متقدم",IF(E7<=المرجع!$F$2,"أولي","جزئي")) -> أولي
A8: القطاع التنفيذي | B8: وكالة (أ) | C8: وحدة أ-١ | D8: مرحلة التصميم | E8: =SUMIFS('الإدخال والحساب'!$I$2:$I$289,'الإدخال والحساب'!$D$2:$D$289,$C8,'الإدخال والحساب'!$E$2:$E$289,$D8) -> 86.1675 | F8: =IF(E8>المرجع!$F$3,"متقدم",IF(E8<=المرجع!$F$2,"أولي","جزئي")) -> متقدم
A9: القطاع التنفيذي | B9: وكالة (أ) | C9: وحدة أ-١ | D9: التفعيل | E9: =SUMIFS('الإدخال والحساب'!$I$2:$I$289,'الإدخال والحساب'!$D$2:$D$289,$C9,'الإدخال والحساب'!$E$2:$E$289,$D9) -> 66.85 | F9: =IF(E9>المرجع!$F$3,"متقدم",IF(E9<=المرجع!$F$2,"أولي","جزئي")) -> جزئي
A10: القطاع التنفيذي | B10: وكالة (أ) | C10: وحدة أ-١ | D10: مرحلة التشغيل | E10: =SUMIFS('الإدخال والحساب'!$I$2:$I$289,'الإدخال والحساب'!$D$2:$D$289,$C10,'الإدخال والحساب'!$E$2:$E$289,$D10) -> 50.9 | F10: =IF(E10>المرجع!$F$3,"متقدم",IF(E10<=المرجع!$F$2,"أولي","جزئي")) -> جزئي
A11: القطاع التنفيذي | B11: وكالة (أ) | C11: وحدة أ-٢ | D11: مرحلة التصميم | E11: =SUMIFS('الإدخال والحساب'!$I$2:$I$289,'الإدخال والحساب'!$D$2:$D$289,$C11,'الإدخال والحساب'!$E$2:$E$289,$D11) -> 25.93 | F11: =IF(E11>المرجع!$F$3,"متقدم",IF(E11<=المرجع!$F$2,"أولي","جزئي")) -> أولي
A12: القطاع التنفيذي | B12: وكالة (أ) | C12: وحدة أ-٢ | D12: التفعيل | E12: =SUMIFS('الإدخال والحساب'!$I$2:$I$289,'الإدخال والحساب'!$D$2:$D$289,$C12,'الإدخال والحساب'!$E$2:$E$289,$D12) -> 60.05 | F12: =IF(E12>المرجع!$F$3,"متقدم",IF(E12<=المرجع!$F$2,"أولي","جزئي")) -> جزئي
A13: القطاع التنفيذي | B13: وكالة (أ) | C13: وحدة أ-٢ | D13: مرحلة التشغيل | E13: =SUMIFS('الإدخال والحساب'!$I$2:$I$289,'الإدخال والحساب'!$D$2:$D$289,$C13,'الإدخال والحساب'!$E$2:$E$289,$D13) -> 49 | F13: =IF(E13>المرجع!$F$3,"متقدم",IF(E13<=المرجع!$F$2,"أولي","جزئي")) -> جزئي
... A49: القطاع التنفيذي | B49: وكالة (و) | C49: وكالة (و) | D49: مرحلة التشغيل | E49: =SUMIFS('الإدخال والحساب'!$I$2:$I$289,'الإدخال والحساب'!$D$2:$D$289,$C49,'الإدخال والحساب'!$E$2:$E$289,$D49) -> 39.25 | F49: =IF(E49>المرجع!$F$3,"متقدم",IF(E49<=المرجع!$F$2,"أولي","جزئي")) -> جزئي

Sheet المرجع
A1: المرحلة | B1: العنصر | C1: الوزن | E1: حدود التصنيف
A2: مرحلة التصميم | B2: الدور | C2: 25 | E2: أولي: أقل من أو يساوي | F2: 30
A3: مرحلة التصميم | B3: الأهداف ومؤشرات الأداء | C3: 15 | E3: متقدم: أعلى من | F3: 70
A4: مرحلة التصميم | B4: الحوكمة | C4: 15 | E4: جزئي: ما بينهما
A5: مرحلة التصميم | B5: التنظيم | C5: 20
A6: مرحلة التصميم | B6: الموارد | C6: 20
A7: مرحلة التصميم | B7: الإجراءات | C7: 5
A8: التفعيل | B8: الدور | C8: 15
A9: التفعيل | B9: الأهداف ومؤشرات الأداء | C9: 15
A10: التفعيل | B10: الحوكمة | C10: 15
A11: التفعيل | B11: التنظيم | C11: 20
A12: التفعيل | B12: الموارد | C12: 25
A13: التفعيل | B13: الإجراءات | C13: 5
A14: التفعيل | B14: إنتاج المخرج الأول | C14: 5
A15: مرحلة التشغيل | B15: الأهداف ومؤشرات الأداء | C15: 25
A16: مرحلة التشغيل | B16: الحوكمة | C16: 15
... A19: مرحلة التشغيل | B19: اكتمال المخرجات المستهدفة | C19: 30
