Workbook

Sheet تعليمات
A1: دليل الاستخدام — قياس نضج النموذج التشغيلي للوحدات التنظيمية
A3: ١) منطق القياس (من الأسفل إلى الأعلى)
A4: نقطة التحقق ← العنصر ← المرحلة ← الوحدة التنظيمية
A5: • تُقاس كل نقطة تحقق على حدة لكل وحدة تنظيمية بنسبة من ٠ إلى ١٠٠، وتُصنَّف تلقائيًا: مستوفاة بشكل أولي ≤ ٣٠، جزئي ٣١–٧٠، متقدم > ٧٠ (نفس حدود التصنيف في «المرجع»).
A6: • نسبة اكتمال العنصر = متوسط نسب نقاط التحقق التابعة له (النقطة غير المقيّمة تُحتسب صفرًا).
A7: • الوزن المكتسب للعنصر = وزن العنصر في المرحلة × نسبة اكتماله ÷ ١٠٠.
A8: • درجة المرحلة = مجموع الأوزان المكتسبة لعناصرها (مجموع أوزان كل مرحلة = ١٠٠). والنضج النهائي المرجّح للوحدة = التصميم×٢٠٪ + البناء المؤسسي×٣٠٪ + التشغيل×٥٠٪ (الأوزان قابلة للتعديل في «المرجع» K9:K11). التصنيف: أولي ≤ ٣٠، جزئي ٣١–٧٠، متقدم > ٧٠.
A9: • التصنيف: أولي ≤ ٣٠، جزئي ٣١–٧٠، متقدم > ٧٠.
A11: ٢) بنية الملف
A12: • «المرجع»: المراحل الثلاث (التصميم / البناء المؤسسي / التشغيل) والعناصر وأوزانها وعدد نقاط التحقق وحدود التصنيف.
A13: • «نقاط التحقق»: نص كل نقطة تحقق وكودها والجهة المزودة للمعلومة (٣٠ نقطة).
A14: • «قائمة الوحدات»: سجل الوحدات المقاسة بأكوادها — نقطة التعريف الوحيدة لأي وحدة.
... A39: • أوراق الإدخال الثلاث متطابقة الأعمدة تمامًا فيمكن دمجها في مصفوفة واحدة بعد القراءة.

Sheet المرجع
A1: المرحلة | B1: كود المرحلة | C1: ترتيب المرحلة | D1: العنصر | E1: كود العنصر | F1: ترتيب العنصر | G1: الوزن في المرحلة % | H1: عدد نقاط التحقق | J1: حدود التصنيف | K1: القيمة
A2: التصميم | B2: DESIGN | C2: 1 | D2: الدور | E2: ROLE | F2: 1 | G2: 25 | H2: 1 | J2: أولي: أقل من أو يساوي | K2: 30
A3: التصميم | B3: DESIGN | C3: 1 | D3: الأهداف ومؤشرات الأداء | E3: KPI | F3: 2 | G3: 15 | H3: 2 | J3: متقدم: أعلى من | K3: 70
A4: التصميم | B4: DESIGN | C4: 1 | D4: الحوكمة | E4: GOV | F4: 3 | G4: 15 | H4: 1 | J4: جزئي: ما بينهما
A5: التصميم | B5: DESIGN | C5: 1 | D5: التنظيم | E5: ORG | F5: 4 | G5: 20 | H5: 1
A6: التصميم | B6: DESIGN | C6: 1 | D6: الموارد | E6: RES | F6: 5 | G6: 20 | H6: 1 | J6: ملاحظة: عدد نقاط التحقق مأخوذ من إطار نقاط التحقق المعتمد (ورقة «نقاط التحقق»).
A7: التصميم | B7: DESIGN | C7: 1 | D7: الإجراءات | E7: PROC | F7: 6 | G7: 5 | H7: 1
A8: البناء المؤسسي | B8: BUILD | C8: 2 | D8: الدور | E8: ROLE | F8: 1 | G8: 15 | H8: 1 | J8: أوزان المراحل للنضج النهائي | K8: الوزن %
A9: البناء المؤسسي | B9: BUILD | C9: 2 | D9: الأهداف ومؤشرات الأداء | E9: KPI | F9: 2 | G9: 15 | H9: 2 | J9: التصميم | K9: 20 | L9: DESIGN
A10: البناء المؤسسي | B10: BUILD | C10: 2 | D10: الحوكمة | E10: GOV | F10: 3 | G10: 15 | H10: 3 | J10: البناء المؤسسي | K10: 30 | L10: BUILD
A11: البناء المؤسسي | B11: BUILD | C11: 2 | D11: التنظيم | E11: ORG | F11: 4 | G11: 20 | H11: 3 | J11: التشغيل | K11: 50 | L11: OPERATE
A12: البناء المؤسسي | B12: BUILD | C12: 2 | D12: الموارد | E12: RES | F12: 5 | G12: 25 | H12: 4 | J12: المجموع يجب أن يساوي ١٠٠
A13: البناء المؤسسي | B13: BUILD | C13: 2 | D13: الإجراءات | E13: PROC | F13: 6 | G13: 5 | H13: 1
A14: البناء المؤسسي | B14: BUILD | C14: 2 | D14: إنتاج المخرج الأول | E14: OUT1 | F14: 7 | G14: 5 | H14: 1
A15: التشغيل | B15: OPERATE | C15: 3 | D15: الأهداف ومؤشرات الأداء | E15: KPI | F15: 2 | G15: 25 | H15: 2
A16: التشغيل | B16: OPERATE | C16: 3 | D16: الحوكمة | E16: GOV | F16: 3 | G16: 15 | H16: 3
A17: التشغيل | B17: OPERATE | C17: 3 | D17: الموارد | E17: RES | F17: 5 | G17: 15 | H17: 1
A18: التشغيل | B18: OPERATE | C18: 3 | D18: الإجراءات | E18: PROC | F18: 6 | G18: 15 | H18: 1
A19: التشغيل | B19: OPERATE | C19: 3 | D19: اكتمال المخرجات المستهدفة | E19: OUTF | F19: 8 | G19: 30 | H19: 1

Sheet نقاط التحقق
A1: كود النقطة | B1: المرحلة | C1: كود المرحلة | D1: العنصر | E1: كود العنصر | F1: رقم النقطة | G1: نص نقطة التحقق | H1: الجهة المزودة للمعلومة
A2: DESIGN-ROLE-1 | B2: التصميم | C2: DESIGN | D2: الدور | E2: ROLE | F2: 1 | G2: دور مفصل للوحدة التنظيمية
A3: DESIGN-KPI-1 | B3: التصميم | C3: DESIGN | D3: الأهداف ومؤشرات الأداء | E3: KPI | F3: 1 | G3: أهداف محددة للوحدة التنظيمية وربطها بمؤشرات أداء لقياسها
A4: DESIGN-KPI-2 | B4: التصميم | C4: DESIGN | D4: الأهداف ومؤشرات الأداء | E4: KPI | F4: 2 | G4: مؤشرات أداء الوحدة التنظيمية
A5: DESIGN-GOV-1 | B5: التصميم | C5: DESIGN | D5: الحوكمة | E5: GOV | F5: 1 | G5: تفصيل القرارات ومصفوفة الصلاحيات واللجان ذات العلاقة لاعتماد مخرجات الوحدة التنظيمية
A6: DESIGN-ORG-1 | B6: التصميم | C6: DESIGN | D6: التنظيم | E6: ORG | F6: 1 | G6: تطوير الأدوار والمسؤوليات للوحدة التنظيمية وتفصيل الهيكل التنظيمي
A7: DESIGN-RES-1 | B7: التصميم | C7: DESIGN | D7: الموارد | E7: RES | F7: 1 | G7: تفصيل احتياج الموارد البشرية للوحدة التنظيمية
A8: DESIGN-PROC-1 | B8: التصميم | C8: DESIGN | D8: الإجراءات | E8: PROC | F8: 1 | G8: تفصيل المخرجات إلى إجراءات عالية المستوى
A9: BUILD-ROLE-1 | B9: البناء المؤسسي | C9: BUILD | D9: الدور | E9: ROLE | F9: 1 | G9: دور معتمد للوحدة التنظيمية
A10: BUILD-KPI-1 | B10: البناء المؤسسي | C10: BUILD | D10: الأهداف ومؤشرات الأداء | E10: KPI | F10: 1 | G10: أهداف تشغيلية معتمدة من صاحب الصلاحية
A11: BUILD-KPI-2 | B11: البناء المؤسسي | C11: BUILD | D11: الأهداف ومؤشرات الأداء | E11: KPI | F11: 2 | G11: نشر الأهداف التشغيلية على موظفي الوحدة التنظيمية
A12: BUILD-GOV-1 | B12: البناء المؤسسي | C12: BUILD | D12: الحوكمة | E12: GOV | F12: 1 | G12: مصفوفة صلاحيات معتمدة ومعممة على أصحاب المصلحة
A13: BUILD-GOV-2 | B13: البناء المؤسسي | C13: BUILD | D13: الحوكمة | E13: GOV | F13: 2 | G13: سياسات معتمدة للتي تملكها الوحدة التنظيمية
... A31: OPERATE-OUTF-1 | B31: التشغيل | C31: OPERATE | D31: اكتمال المخرجات المستهدفة | E31: OUTF | F31: 1 | G31: اكتمال مخرجات النموذج التشغيلي المستهدف للوحدة التنظيمية

Sheet قائمة الوحدات
A1: كود الوحدة | B1: كود المجموعة | C1: المجموعة | D1: الوحدة التنظيمية الرئيسية | E1: الوحدة التنظيمية الفرعية | F1: الوحدة المقاسة | G1: مستوى الوحدة | H1: ورقة الإدخال | I1: عدد نقاط التحقق المقاسة
A2: TOP-01 | B2: TOP | C2: المرتبطة بسمو الوزير | D2: المكتب التنفيذي | E2: — | F2: =IF($E2="—",$D2,$E2) -> المكتب التنفيذي | G2: إدارة | H2: المرتبطة بالمسؤول الأول | I2: =COUNTIF('المرتبطة بسمو الوزير'!$B$2:$B$700,$A2) -> 30
A3: TOP-02 | B3: TOP | C3: المرتبطة بسمو الوزير | D3: إدارة المتابعة والتقارير | E3: — | F3: =IF($E3="—",$D3,$E3) -> إدارة المتابعة والتقارير | G3: إدارة | H3: المرتبطة بالمسؤول الأول | I3: =COUNTIF('المرتبطة بسمو الوزير'!$B$2:$B$700,$A3) -> 30
A4: TOP-03 | B4: TOP | C4: المرتبطة بسمو الوزير | D4: إدارة الحوكمة والمخاطر | E4: — | F4: =IF($E4="—",$D4,$E4) -> إدارة الحوكمة والمخاطر | G4: إدارة | H4: المرتبطة بالمسؤول الأول | I4: =COUNTIF('المرتبطة بسمو الوزير'!$B$2:$B$700,$A4) -> 30
A5: TOP-04 | B5: TOP | C5: المرتبطة بسمو الوزير | D5: إدارة الشؤون القانونية | E5: — | F5: =IF($E5="—",$D5,$E5) -> إدارة الشؤون القانونية | G5: إدارة | H5: المرتبطة بالمسؤول الأول | I5: =COUNTIF('المرتبطة بسمو الوزير'!$B$2:$B$700,$A5) -> 30
A6: TOP-05 | B6: TOP | C6: المرتبطة بسمو الوزير | D6: إدارة التميز المؤسسي | E6: — | F6: =IF($E6="—",$D6,$E6) -> إدارة التميز المؤسسي | G6: إدارة | H6: المرتبطة بالمسؤول الأول | I6: =COUNTIF('المرتبطة بسمو الوزير'!$B$2:$B$700,$A6) -> 30
A7: EXE-01 | B7: EXE | C7: الشؤون التنفيذية | D7: وكالة الشؤون الفنية | E7: الإدارة العامة للتخطيط والدراسات | F7: =IF($E7="—",$D7,$E7) -> الإدارة العامة للتخطيط والدراسات | G7: إدارة عامة | H7: الشؤون التنفيذية | I7: =COUNTIF('الشؤون التنفيذية'!$B$2:$B$700,$A7) -> 30
A8: EXE-02 | B8: EXE | C8: الشؤون التنفيذية | D8: وكالة الشؤون الفنية | E8: الإدارة العامة للجودة والتطوير | F8: =IF($E8="—",$D8,$E8) -> الإدارة العامة للجودة والتطوير | G8: إدارة عامة | H8: الشؤون التنفيذية | I8: =COUNTIF('الشؤون التنفيذية'!$B$2:$B$700,$A8) -> 30
A9: EXE-03 | B9: EXE | C9: الشؤون التنفيذية | D9: وكالة الشؤون الفنية | E9: الإدارة العامة للمشاريع | F9: =IF($E9="—",$D9,$E9) -> الإدارة العامة للمشاريع | G9: إدارة عامة | H9: الشؤون التنفيذية | I9: =COUNTIF('الشؤون التنفيذية'!$B$2:$B$700,$A9) -> 30
A10: EXE-04 | B10: EXE | C10: الشؤون التنفيذية | D10: وكالة الشؤون الفنية | E10: الإدارة العامة للتشغيل والصيانة | F10: =IF($E10="—",$D10,$E10) -> الإدارة العامة للتشغيل والصيانة | G10: إدارة عامة | H10: الشؤون التنفيذية | I10: =COUNTIF('الشؤون التنفيذية'!$B$2:$B$700,$A10) -> 30
A11: EXE-05 | B11: EXE | C11: الشؤون التنفيذية | D11: وكالة الشؤون الفنية | E11: الإدارة العامة للسلامة والبيئة | F11: =IF($E11="—",$D11,$E11) -> الإدارة العامة للسلامة والبيئة | G11: إدارة عامة | H11: الشؤون التنفيذية | I11: =COUNTIF('الشؤون التنفيذية'!$B$2:$B$700,$A11) -> 30
A12: EXE-06 | B12: EXE | C12: الشؤون التنفيذية | D12: وكالة الشؤون الفنية | E12: الإدارة العامة للأصول والمرافق | F12: =IF($E12="—",$D12,$E12) -> الإدارة العامة للأصول والمرافق | G12: إدارة عامة | H12: الشؤون التنفيذية | I12: =COUNTIF('الشؤون التنفيذية'!$B$2:$B$700,$A12) -> 30
A13: EXE-07 | B13: EXE | C13: الشؤون التنفيذية | D13: وكالة الشؤون الفنية | E13: الإدارة العامة للأمن والحماية | F13: =IF($E13="—",$D13,$E13) -> الإدارة العامة للأمن والحماية | G13: إدارة عامة | H13: الشؤون التنفيذية | I13: =COUNTIF('الشؤون التنفيذية'!$B$2:$B$700,$A13) -> 30
A14: EXE-08 | B14: EXE | C14: الشؤون التنفيذية | D14: وكالة الخدمات المساندة | E14: الإدارة العامة للموارد البشرية | F14: =IF($E14="—",$D14,$E14) -> الإدارة العامة للموارد البشرية | G14: إدارة عامة | H14: الشؤون التنفيذية | I14: =COUNTIF('الشؤون التنفيذية'!$B$2:$B$700,$A14) -> 30
A15: EXE-09 | B15: EXE | C15: الشؤون التنفيذية | D15: وكالة الخدمات المساندة | E15: الإدارة العامة للشؤون المالية | F15: =IF($E15="—",$D15,$E15) -> الإدارة العامة للشؤون المالية | G15: إدارة عامة | H15: الشؤون التنفيذية | I15: =COUNTIF('الشؤون التنفيذية'!$B$2:$B$700,$A15) -> 30
A16: EXE-10 | B16: EXE | C16: الشؤون التنفيذية | D16: وكالة الخدمات المساندة | E16: الإدارة العامة لتقنية المعلومات | F16: =IF($E16="—",$D16,$E16) -> الإدارة العامة لتقنية المعلومات | G16: إدارة عامة | H16: الشؤون التنفيذية | I16: =COUNTIF('الشؤون التنفيذية'!$B$2:$B$700,$A16) -> 30
A17: EXE-11 | B17: EXE | C17: الشؤون التنفيذية | D17: وكالة الشؤون الاستراتيجية | E17: — | F17: =IF($E17="—",$D17,$E17) -> وكالة الشؤون الاستراتيجية | G17: وكالة | H17: الشؤون التنفيذية | I17: =COUNTIF('الشؤون التنفيذية'!$B$2:$B$700,$A17) -> 30
A18: EXE-12 | B18: EXE | C18: الشؤون التنفيذية | D18: وكالة التحول الرقمي | E18: — | F18: =IF($E18="—",$D18,$E18) -> وكالة التحول الرقمي | G18: وكالة | H18: الشؤون التنفيذية | I18: =COUNTIF('الشؤون التنفيذية'!$B$2:$B$700,$A18) -> 30
... A20: EXE-14 | B20: EXE | C20: الشؤون التنفيذية | D20: وكالة الرقابة والالتزام | E20: — | F20: =IF($E20="—",$D20,$E20) -> وكالة الرقابة والالتزام | G20: وكالة | H20: الشؤون التنفيذية | I20: =COUNTIF('الشؤون التنفيذية'!$B$2:$B$700,$A20) -> 30
A21: MIL-01 | B21: MIL | C21: الجهاز العسكري | D21: هيئة الأركان | E21: — | F21: =IF($E21="—",$D21,$E21) -> هيئة الأركان | G21: إدارة | H21: الجهاز العسكري | I21: =COUNTIF('الجهاز العسكري'!$B$2:$B$700,$A21) -> 30
A22: MIL-02 | B22: MIL | C22: الجهاز العسكري | D22: قيادة القوات البرية | E22: — | F22: =IF($E22="—",$D22,$E22) -> قيادة القوات البرية | G22: إدارة | H22: الجهاز العسكري | I22: =COUNTIF('الجهاز العسكري'!$B$2:$B$700,$A22) -> 30
A23: MIL-03 | B23: MIL | C23: الجهاز العسكري | D23: قيادة القوات الجوية | E23: — | F23: =IF($E23="—",$D23,$E23) -> قيادة القوات الجوية | G23: إدارة | H23: الجهاز العسكري | I23: =COUNTIF('الجهاز العسكري'!$B$2:$B$700,$A23) -> 30
A24: MIL-04 | B24: MIL | C24: الجهاز العسكري | D24: قيادة القوات البحرية | E24: — | F24: =IF($E24="—",$D24,$E24) -> قيادة القوات البحرية | G24: إدارة | H24: الجهاز العسكري | I24: =COUNTIF('الجهاز العسكري'!$B$2:$B$700,$A24) -> 30
A25: MIL-05 | B25: MIL | C25: الجهاز العسكري | D25: قيادة قوات الدفاع الجوي | E25: — | F25: =IF($E25="—",$D25,$E25) -> قيادة قوات الدفاع الجوي | G25: إدارة | H25: الجهاز العسكري | I25: =COUNTIF('الجهاز العسكري'!$B$2:$B$700,$A25) -> 30
A26: MIL-06 | B26: MIL | C26: الجهاز العسكري | D26: قيادة القوات الاستراتيجية | E26: — | F26: =IF($E26="—",$D26,$E26) -> قيادة القوات الاستراتيجية | G26: إدارة | H26: الجهاز العسكري | I26: =COUNTIF('الجهاز العسكري'!$B$2:$B$700,$A26) -> 30
A27: MIL-07 | B27: MIL | C27: الجهاز العسكري | D27: الإدارة العامة للاستخبارات العسكرية | E27: — | F27: =IF($E27="—",$D27,$E27) -> الإدارة العامة للاستخبارات العسكرية | G27: إدارة | H27: الجهاز العسكري | I27: =COUNTIF('الجهاز العسكري'!$B$2:$B$700,$A27) -> 30
A28: MIL-08 | B28: MIL | C28: الجهاز العسكري | D28: الإدارة العامة للعمليات المشتركة | E28: — | F28: =IF($E28="—",$D28,$E28) -> الإدارة العامة للعمليات المشتركة | G28: إدارة | H28: الجهاز العسكري | I28: =COUNTIF('الجهاز العسكري'!$B$2:$B$700,$A28) -> 30
A29: MIL-09 | B29: MIL | C29: الجهاز العسكري | D29: الإدارة العامة للتخطيط والتنظيم العسكري | E29: — | F29: =IF($E29="—",$D29,$E29) -> الإدارة العامة للتخطيط والتنظيم العسكري | G29: إدارة | H29: الجهاز العسكري | I29: =COUNTIF('الجهاز العسكري'!$B$2:$B$700,$A29) -> 30
A30: MIL-10 | B30: MIL | C30: الجهاز العسكري | D30: الإدارة العامة للإمداد والتموين | E30: — | F30: =IF($E30="—",$D30,$E30) -> الإدارة العامة للإمداد والتموين | G30: إدارة | H30: الجهاز العسكري | I30: =COUNTIF('الجهاز العسكري'!$B$2:$B$700,$A30) -> 30
A31: MIL-11 | B31: MIL | C31: الجهاز العسكري | D31: الإدارة العامة للاتصالات وتقنية المعلومات العسكرية | E31: — | F31: =IF($E31="—",$D31,$E31) -> الإدارة العامة للاتصالات وتقنية المعلومات العسكرية | G31: إدارة | H31: الجهاز العسكري | I31: =COUNTIF('الجهاز العسكري'!$B$2:$B$700,$A31) -> 30
A32: MIL-12 | B32: MIL | C32: الجهاز العسكري | D32: الإدارة العامة للشؤون الهندسية العسكرية | E32: — | F32: =IF($E32="—",$D32,$E32) -> الإدارة العامة للشؤون الهندسية العسكرية | G32: إدارة | H32: الجهاز العسكري | I32: =COUNTIF('الجهاز العسكري'!$B$2:$B$700,$A32) -> 30
... A41: MIL-21 | B41: MIL | C41: الجهاز العسكري | D41: الإدارة العامة للمراسم والتشريفات العسكرية | E41: — | F41: =IF($E41="—",$D41,$E41) -> الإدارة العامة للمراسم والتشريفات العسكرية | G41: إدارة | H41: الجهاز العسكري | I41: =COUNTIF('الجهاز العسكري'!$B$2:$B$700,$A41) -> 30

Sheet المرتبطة بسمو الوزير
A1: معرف الصف | B1: كود الوحدة | C1: كود المجموعة | D1: القطاع | E1: الوحدة التنظيمية الرئيسية | F1: الوحدة التنظيمية الفرعية | G1: كود المرحلة | H1: المرحلة | I1: كود العنصر | J1: العنصر | K1: كود النقطة | L1: نص نقطة التحقق | M1: نسبة إنجاز النقطة % | N1: نسبة إنجاز النقطة المستهدفة لعام 2026 % | O1: حالة النقطة | P1: ملاحظات النقطة
A2: TOP-01-DESIGN-ROLE-1 | B2: TOP-01 | C2: =IFERROR(INDEX('قائمة الوحدات'!$B$2:$B$41,MATCH($B2,'قائمة الوحدات'!$A$2:$A$41,0)),"") -> TOP | D2: =IFERROR(INDEX('قائمة الوحدات'!$C$2:$C$41,MATCH($B2,'قائمة الوحدات'!$A$2:$A$41,0)),"") -> المرتبطة بسمو الوزير | E2: =IFERROR(INDEX('قائمة الوحدات'!$D$2:$D$41,MATCH($B2,'قائمة الوحدات'!$A$2:$A$41,0)),"") -> المكتب التنفيذي | F2: =IFERROR(INDEX('قائمة الوحدات'!$F$2:$F$41,MATCH($B2,'قائمة الوحدات'!$A$2:$A$41,0)),"") -> المكتب التنفيذي | G2: DESIGN | H2: =IFERROR(INDEX(المرجع!$A$2:$A$19,MATCH($G2,المرجع!$B$2:$B$19,0)),"") -> التصميم | I2: ROLE | J2: =IFERROR(INDEX(المرجع!$D$2:$D$19,MATCH($I2,المرجع!$E$2:$E$19,0)),"") -> الدور | K2: DESIGN-ROLE-1 | L2: =IFERROR(INDEX('نقاط التحقق'!$G$2:$G$31,MATCH($K2,'نقاط التحقق'!$A$2:$A$31,0))&"","") -> دور مفصل للوحدة التنظيمية | M2: 50 | N2: 90 | O2: =IF($M2="","غير مقيّمة",IF($M2>المرجع!$K$3,"مستوفاة بشكل متقدم",IF($M2<=المرجع!$K$2,"مستوفاة بشكل أولي","مستوفاة بشكل جزئي"))) -> مستوفاة بشكل جزئي | P2: الملاحظات فيذا
A3: TOP-01-DESIGN-KPI-1 | B3: TOP-01 | C3: =IFERROR(INDEX('قائمة الوحدات'!$B$2:$B$41,MATCH($B3,'قائمة الوحدات'!$A$2:$A$41,0)),"") -> TOP | D3: =IFERROR(INDEX('قائمة الوحدات'!$C$2:$C$41,MATCH($B3,'قائمة الوحدات'!$A$2:$A$41,0)),"") -> المرتبطة بسمو الوزير | E3: =IFERROR(INDEX('قائمة الوحدات'!$D$2:$D$41,MATCH($B3,'قائمة الوحدات'!$A$2:$A$41,0)),"") -> المكتب التنفيذي | F3: =IFERROR(INDEX('قائمة الوحدات'!$F$2:$F$41,MATCH($B3,'قائمة الوحدات'!$A$2:$A$41,0)),"") -> المكتب التنفيذي | G3: DESIGN | H3: =IFERROR(INDEX(المرجع!$A$2:$A$19,MATCH($G3,المرجع!$B$2:$B$19,0)),"") -> التصميم | I3: KPI | J3: =IFERROR(INDEX(المرجع!$D$2:$D$19,MATCH($I3,المرجع!$E$2:$E$19,0)),"") -> الأهداف ومؤشرات الأداء | K3: DESIGN-KPI-1 | L3: =IFERROR(INDEX('نقاط التحقق'!$G$2:$G$31,MATCH($K3,'نقاط التحقق'!$A$2:$A$31,0))&"","") -> أهداف محددة للوحدة التنظيمية وربطها بمؤشرات أداء لقياسها | M3: 85 | N3: 85 | O3: =IF($M3="","غير مقيّمة",IF($M3>المرجع!$K$3,"مستوفاة بشكل متقدم",IF($M3<=المرجع!$K$2,"مستوفاة بشكل أولي","مستوفاة بشكل جزئي"))) -> مستوفاة بشكل متقدم | P3: الملاحظات فيذا
A4: TOP-01-DESIGN-KPI-2 | B4: TOP-01 | C4: =IFERROR(INDEX('قائمة الوحدات'!$B$2:$B$41,MATCH($B4,'قائمة الوحدات'!$A$2:$A$41,0)),"") -> TOP | D4: =IFERROR(INDEX('قائمة الوحدات'!$C$2:$C$41,MATCH($B4,'قائمة الوحدات'!$A$2:$A$41,0)),"") -> المرتبطة بسمو الوزير | E4: =IFERROR(INDEX('قائمة الوحدات'!$D$2:$D$41,MATCH($B4,'قائمة الوحدات'!$A$2:$A$41,0)),"") -> المكتب التنفيذي | F4: =IFERROR(INDEX('قائمة الوحدات'!$F$2:$F$41,MATCH($B4,'قائمة الوحدات'!$A$2:$A$41,0)),"") -> المكتب التنفيذي | G4: DESIGN | H4: =IFERROR(INDEX(المرجع!$A$2:$A$19,MATCH($G4,المرجع!$B$2:$B$19,0)),"") -> التصميم | I4: KPI | J4: =IFERROR(INDEX(المرجع!$D$2:$D$19,MATCH($I4,المرجع!$E$2:$E$19,0)),"") -> الأهداف ومؤشرات الأداء | K4: DESIGN-KPI-2 | L4: =IFERROR(INDEX('نقاط التحقق'!$G$2:$G$31,MATCH($K4,'نقاط التحقق'!$A$2:$A$31,0))&"","") -> مؤشرات أداء الوحدة التنظيمية | M4: 60 | N4: 95 | O4: =IF($M4="","غير مقيّمة",IF($M4>المرجع!$K$3,"مستوفاة بشكل متقدم",IF($M4<=المرجع!$K$2,"مستوفاة بشكل أولي","مستوفاة بشكل جزئي"))) -> مستوفاة بشكل جزئي | P4: الملاحظات فيذا
A5: TOP-01-DESIGN-GOV-1 | B5: TOP-01 | C5: =IFERROR(INDEX('قائمة الوحدات'!$B$2:$B$41,MATCH($B5,'قائمة الوحدات'!$A$2:$A$41,0)),"") -> TOP | D5: =IFERROR(INDEX('قائمة الوحدات'!$C$2:$C$41,MATCH($B5,'قائمة الوحدات'!$A$2:$A$41,0)),"") -> المرتبطة بسمو الوزير | E5: =IFERROR(INDEX('قائمة الوحدات'!$D$2:$D$41,MATCH($B5,'قائمة الوحدات'!$A$2:$A$41,0)),"") -> المكتب التنفيذي | F5: =IFERROR(INDEX('قائمة الوحدات'!$F$2:$F$41,MATCH($B5,'قائمة الوحدات'!$A$2:$A$41,0)),"") -> المكتب التنفيذي | G5: DESIGN | H5: =IFERROR(INDEX(المرجع!$A$2:$A$19,MATCH($G5,المرجع!$B$2:$B$19,0)),"") -> التصميم | I5: GOV | J5: =IFERROR(INDEX(المرجع!$D$2:$D$19,MATCH($I5,المرجع!$E$2:$E$19,0)),"") -> الحوكمة | K5: DESIGN-GOV-1 | L5: =IFERROR(INDEX('نقاط التحقق'!$G$2:$G$31,MATCH($K5,'نقاط التحقق'!$A$2:$A$31,0))&"","") -> تفصيل القرارات ومصفوفة الصلاحيات واللجان ذات العلاقة لاعتماد مخرجات الوحدة التنظيمية | M5: 87 | N5: 100 | O5: =IF($M5="","غير مقيّمة",IF($M5>المرجع!$K$3,"مستوفاة بشكل متقدم",IF($M5<=المرجع!$K$2,"مستوفاة بشكل أولي","مستوفاة بشكل جزئي"))) -> مستوفاة بشكل متقدم | P5: الملاحظات فيذا
A6: TOP-01-DESIGN-ORG-1 | B6: TOP-01 | C6: =IFERROR(INDEX('قائمة الوحدات'!$B$2:$B$41,MATCH($B6,'قائمة الوحدات'!$A$2:$A$41,0)),"") -> TOP | D6: =IFERROR(INDEX('قائمة الوحدات'!$C$2:$C$41,MATCH($B6,'قائمة الوحدات'!$A$2:$A$41,0)),"") -> المرتبطة بسمو الوزير | E6: =IFERROR(INDEX('قائمة الوحدات'!$D$2:$D$41,MATCH($B6,'قائمة الوحدات'!$A$2:$A$41,0)),"") -> المكتب التنفيذي | F6: =IFERROR(INDEX('قائمة الوحدات'!$F$2:$F$41,MATCH($B6,'قائمة الوحدات'!$A$2:$A$41,0)),"") -> المكتب التنفيذي | G6: DESIGN | H6: =IFERROR(INDEX(المرجع!$A$2:$A$19,MATCH($G6,المرجع!$B$2:$B$19,0)),"") -> التصميم | I6: ORG | J6: =IFERROR(INDEX(المرجع!$D$2:$D$19,MATCH($I6,المرجع!$E$2:$E$19,0)),"") -> التنظيم | K6: DESIGN-ORG-1 | L6: =IFERROR(INDEX('نقاط التحقق'!$G$2:$G$31,MATCH($K6,'نقاط التحقق'!$A$2:$A$31,0))&"","") -> تطوير الأدوار والمسؤوليات للوحدة التنظيمية وتفصيل الهيكل التنظيمي | M6: 82 | N6: 82 | O6: =IF($M6="","غير مقيّمة",IF($M6>المرجع!$K$3,"مستوفاة بشكل متقدم",IF($M6<=المرجع!$K$2,"مستوفاة بشكل أولي","مستوفاة بشكل جزئي"))) -> مستوفاة بشكل متقدم | P6: الملاحظات فيذا
A7: TOP-01-DESIGN-RES-1 | B7: TOP-01 | C7: =IFERROR(INDEX('قائمة الوحدات'!$B$2:$B$41,MATCH($B7,'قائمة الوحدات'!$A$2:$A$41,0)),"") -> TOP | D7: =IFERROR(INDEX('قائمة الوحدات'!$C$2:$C$41,MATCH($B7,'قائمة الوحدات'!$A$2:$A$41,0)),"") -> المرتبطة بسمو الوزير | E7: =IFERROR(INDEX('قائمة الوحدات'!$D$2:$D$41,MATCH($B7,'قائمة الوحدات'!$A$2:$A$41,0)),"") -> المكتب التنفيذي | F7: =IFERROR(INDEX('قائمة الوحدات'!$F$2:$F$41,MATCH($B7,'قائمة الوحدات'!$A$2:$A$41,0)),"") -> المكتب التنفيذي | G7: DESIGN | H7: =IFERROR(INDEX(المرجع!$A$2:$A$19,MATCH($G7,المرجع!$B$2:$B$19,0)),"") -> التصميم | I7: RES | J7: =IFERROR(INDEX(المرجع!$D$2:$D$19,MATCH($I7,المرجع!$E$2:$E$19,0)),"") -> الموارد | K7: DESIGN-RES-1 | L7: =IFERROR(INDEX('نقاط التحقق'!$G$2:$G$31,MATCH($K7,'نقاط التحقق'!$A$2:$A$31,0))&"","") -> تفصيل احتياج الموارد البشرية للوحدة التنظيمية | M7: 96 | N7: 96 | O7: =IF($M7="","غير مقيّمة",IF($M7>المرجع!$K$3,"مستوفاة بشكل متقدم",IF($M7<=المرجع!$K$2,"مستوفاة بشكل أولي","مستوفاة بشكل جزئي"))) -> مستوفاة بشكل متقدم | P7: الملاحظات فيذا
A8: TOP-01-DESIGN-PROC-1 | B8: TOP-01 | C8: =IFERROR(INDEX('قائمة الوحدات'!$B$2:$B$41,MATCH($B8,'قائمة الوحدات'!$A$2:$A$41,0)),"") -> TOP | D8: =IFERROR(INDEX('قائمة الوحدات'!$C$2:$C$41,MATCH($B8,'قائمة الوحدات'!$A$2:$A$41,0)),"") -> المرتبطة بسمو الوزير | E8: =IFERROR(INDEX('قائمة الوحدات'!$D$2:$D$41,MATCH($B8,'قائمة الوحدات'!$A$2:$A$41,0)),"") -> المكتب التنفيذي | F8: =IFERROR(INDEX('قائمة الوحدات'!$F$2:$F$41,MATCH($B8,'قائمة الوحدات'!$A$2:$A$41,0)),"") -> المكتب التنفيذي | G8: DESIGN | H8: =IFERROR(INDEX(المرجع!$A$2:$A$19,MATCH($G8,المرجع!$B$2:$B$19,0)),"") -> التصميم | I8: PROC | J8: =IFERROR(INDEX(المرجع!$D$2:$D$19,MATCH($I8,المرجع!$E$2:$E$19,0)),"") -> الإجراءات | K8: DESIGN-PROC-1 | L8: =IFERROR(INDEX('نقاط التحقق'!$G$2:$G$31,MATCH($K8,'نقاط التحقق'!$A$2:$A$31,0))&"","") -> تفصيل المخرجات إلى إجراءات عالية المستوى | M8: 75 | N8: 100 | O8: =IF($M8="","غير مقيّمة",IF($M8>المرجع!$K$3,"مستوفاة بشكل متقدم",IF($M8<=المرجع!$K$2,"مستوفاة بشكل أولي","مستوفاة بشكل جزئي"))) -> مستوفاة بشكل متقدم | P8: الملاحظات فيذا
A9: TOP-01-BUILD-ROLE-1 | B9: TOP-01 | C9: =IFERROR(INDEX('قائمة الوحدات'!$B$2:$B$41,MATCH($B9,'قائمة الوحدات'!$A$2:$A$41,0)),"") -> TOP | D9: =IFERROR(INDEX('قائمة الوحدات'!$C$2:$C$41,MATCH($B9,'قائمة الوحدات'!$A$2:$A$41,0)),"") -> المرتبطة بسمو الوزير | E9: =IFERROR(INDEX('قائمة الوحدات'!$D$2:$D$41,MATCH($B9,'قائمة الوحدات'!$A$2:$A$41,0)),"") -> المكتب التنفيذي | F9: =IFERROR(INDEX('قائمة الوحدات'!$F$2:$F$41,MATCH($B9,'قائمة الوحدات'!$A$2:$A$41,0)),"") -> المكتب التنفيذي | G9: BUILD | H9: =IFERROR(INDEX(المرجع!$A$2:$A$19,MATCH($G9,المرجع!$B$2:$B$19,0)),"") -> البناء المؤسسي | I9: ROLE | J9: =IFERROR(INDEX(المرجع!$D$2:$D$19,MATCH($I9,المرجع!$E$2:$E$19,0)),"") -> الدور | K9: BUILD-ROLE-1 | L9: =IFERROR(INDEX('نقاط التحقق'!$G$2:$G$31,MATCH($K9,'نقاط التحقق'!$A$2:$A$31,0))&"","") -> دور معتمد للوحدة التنظيمية | M9: 55 | N9: 100 | O9: =IF($M9="","غير مقيّمة",IF($M9>المرجع!$K$3,"مستوفاة بشكل متقدم",IF($M9<=المرجع!$K$2,"مستوفاة بشكل أولي","مستوفاة بشكل جزئي"))) -> مستوفاة بشكل جزئي | P9: الملاحظات فيذا
A10: TOP-01-BUILD-KPI-1 | B10: TOP-01 | C10: =IFERROR(INDEX('قائمة الوحدات'!$B$2:$B$41,MATCH($B10,'قائمة الوحدات'!$A$2:$A$41,0)),"") -> TOP | D10: =IFERROR(INDEX('قائمة الوحدات'!$C$2:$C$41,MATCH($B10,'قائمة الوحدات'!$A$2:$A$41,0)),"") -> المرتبطة بسمو الوزير | E10: =IFERROR(INDEX('قائمة الوحدات'!$D$2:$D$41,MATCH($B10,'قائمة الوحدات'!$A$2:$A$41,0)),"") -> المكتب التنفيذي | F10: =IFERROR(INDEX('قائمة الوحدات'!$F$2:$F$41,MATCH($B10,'قائمة الوحدات'!$A$2:$A$41,0)),"") -> المكتب التنفيذي | G10: BUILD | H10: =IFERROR(INDEX(المرجع!$A$2:$A$19,MATCH($G10,المرجع!$B$2:$B$19,0)),"") -> البناء المؤسسي | I10: KPI | J10: =IFERROR(INDEX(المرجع!$D$2:$D$19,MATCH($I10,المرجع!$E$2:$E$19,0)),"") -> الأهداف ومؤشرات الأداء | K10: BUILD-KPI-1 | L10: =IFERROR(INDEX('نقاط التحقق'!$G$2:$G$31,MATCH($K10,'نقاط التحقق'!$A$2:$A$31,0))&"","") -> أهداف تشغيلية معتمدة من صاحب الصلاحية | M10: 70 | N10: 80 | O10: =IF($M10="","غير مقيّمة",IF($M10>المرجع!$K$3,"مستوفاة بشكل متقدم",IF($M10<=المرجع!$K$2,"مستوفاة بشكل أولي","مستوفاة بشكل جزئي"))) -> مستوفاة بشكل جزئي | P10: الملاحظات فيذا
A11: TOP-01-BUILD-KPI-2 | B11: TOP-01 | C11: =IFERROR(INDEX('قائمة الوحدات'!$B$2:$B$41,MATCH($B11,'قائمة الوحدات'!$A$2:$A$41,0)),"") -> TOP | D11: =IFERROR(INDEX('قائمة الوحدات'!$C$2:$C$41,MATCH($B11,'قائمة الوحدات'!$A$2:$A$41,0)),"") -> المرتبطة بسمو الوزير | E11: =IFERROR(INDEX('قائمة الوحدات'!$D$2:$D$41,MATCH($B11,'قائمة الوحدات'!$A$2:$A$41,0)),"") -> المكتب التنفيذي | F11: =IFERROR(INDEX('قائمة الوحدات'!$F$2:$F$41,MATCH($B11,'قائمة الوحدات'!$A$2:$A$41,0)),"") -> المكتب التنفيذي | G11: BUILD | H11: =IFERROR(INDEX(المرجع!$A$2:$A$19,MATCH($G11,المرجع!$B$2:$B$19,0)),"") -> البناء المؤسسي | I11: KPI | J11: =IFERROR(INDEX(المرجع!$D$2:$D$19,MATCH($I11,المرجع!$E$2:$E$19,0)),"") -> الأهداف ومؤشرات الأداء | K11: BUILD-KPI-2 | L11: =IFERROR(INDEX('نقاط التحقق'!$G$2:$G$31,MATCH($K11,'نقاط التحقق'!$A$2:$A$31,0))&"","") -> نشر الأهداف التشغيلية على موظفي الوحدة التنظيمية | M11: 80 | N11: 90 | O11: =IF($M11="","غير مقيّمة",IF($M11>المرجع!$K$3,"مستوفاة بشكل متقدم",IF($M11<=المرجع!$K$2,"مستوفاة بشكل أولي","مستوفاة بشكل جزئي"))) -> مستوفاة بشكل متقدم | P11: الملاحظات فيذا
A12: TOP-01-BUILD-GOV-1 | B12: TOP-01 | C12: =IFERROR(INDEX('قائمة الوحدات'!$B$2:$B$41,MATCH($B12,'قائمة الوحدات'!$A$2:$A$41,0)),"") -> TOP | D12: =IFERROR(INDEX('قائمة الوحدات'!$C$2:$C$41,MATCH($B12,'قائمة الوحدات'!$A$2:$A$41,0)),"") -> المرتبطة بسمو الوزير | E12: =IFERROR(INDEX('قائمة الوحدات'!$D$2:$D$41,MATCH($B12,'قائمة الوحدات'!$A$2:$A$41,0)),"") -> المكتب التنفيذي | F12: =IFERROR(INDEX('قائمة الوحدات'!$F$2:$F$41,MATCH($B12,'قائمة الوحدات'!$A$2:$A$41,0)),"") -> المكتب التنفيذي | G12: BUILD | H12: =IFERROR(INDEX(المرجع!$A$2:$A$19,MATCH($G12,المرجع!$B$2:$B$19,0)),"") -> البناء المؤسسي | I12: GOV | J12: =IFERROR(INDEX(المرجع!$D$2:$D$19,MATCH($I12,المرجع!$E$2:$E$19,0)),"") -> الحوكمة | K12: BUILD-GOV-1 | L12: =IFERROR(INDEX('نقاط التحقق'!$G$2:$G$31,MATCH($K12,'نقاط التحقق'!$A$2:$A$31,0))&"","") -> مصفوفة صلاحيات معتمدة ومعممة على أصحاب المصلحة | M12: 90 | N12: 100 | O12: =IF($M12="","غير مقيّمة",IF($M12>المرجع!$K$3,"مستوفاة بشكل متقدم",IF($M12<=المرجع!$K$2,"مستوفاة بشكل أولي","مستوفاة بشكل جزئي"))) -> مستوفاة بشكل متقدم | P12: الملاحظات فيذا
A13: TOP-01-BUILD-GOV-2 | B13: TOP-01 | C13: =IFERROR(INDEX('قائمة الوحدات'!$B$2:$B$41,MATCH($B13,'قائمة الوحدات'!$A$2:$A$41,0)),"") -> TOP | D13: =IFERROR(INDEX('قائمة الوحدات'!$C$2:$C$41,MATCH($B13,'قائمة الوحدات'!$A$2:$A$41,0)),"") -> المرتبطة بسمو الوزير | E13: =IFERROR(INDEX('قائمة الوحدات'!$D$2:$D$41,MATCH($B13,'قائمة الوحدات'!$A$2:$A$41,0)),"") -> المكتب التنفيذي | F13: =IFERROR(INDEX('قائمة الوحدات'!$F$2:$F$41,MATCH($B13,'قائمة الوحدات'!$A$2:$A$41,0)),"") -> المكتب التنفيذي | G13: BUILD | H13: =IFERROR(INDEX(المرجع!$A$2:$A$19,MATCH($G13,المرجع!$B$2:$B$19,0)),"") -> البناء المؤسسي | I13: GOV | J13: =IFERROR(INDEX(المرجع!$D$2:$D$19,MATCH($I13,المرجع!$E$2:$E$19,0)),"") -> الحوكمة | K13: BUILD-GOV-2 | L13: =IFERROR(INDEX('نقاط التحقق'!$G$2:$G$31,MATCH($K13,'نقاط التحقق'!$A$2:$A$31,0))&"","") -> سياسات معتمدة للتي تملكها الوحدة التنظيمية | M13: 60 | N13: 80 | O13: =IF($M13="","غير مقيّمة",IF($M13>المرجع!$K$3,"مستوفاة بشكل متقدم",IF($M13<=المرجع!$K$2,"مستوفاة بشكل أولي","مستوفاة بشكل جزئي"))) -> مستوفاة بشكل جزئي | P13: الملاحظات فيذا
... A151: TOP-05-OPERATE-OUTF-1 | B151: TOP-05 | C151: =IFERROR(INDEX('قائمة الوحدات'!$B$2:$B$41,MATCH($B151,'قائمة الوحدات'!$A$2:$A$41,0)),"") -> TOP | D151: =IFERROR(INDEX('قائمة الوحدات'!$C$2:$C$41,MATCH($B151,'قائمة الوحدات'!$A$2:$A$41,0)),"") -> المرتبطة بسمو الوزير | E151: =IFERROR(INDEX('قائمة الوحدات'!$D$2:$D$41,MATCH($B151,'قائمة الوحدات'!$A$2:$A$41,0)),"") -> إدارة التميز المؤسسي | F151: =IFERROR(INDEX('قائمة الوحدات'!$F$2:$F$41,MATCH($B151,'قائمة الوحدات'!$A$2:$A$41,0)),"") -> إدارة التميز المؤسسي | G151: OPERATE | H151: =IFERROR(INDEX(المرجع!$A$2:$A$19,MATCH($G151,المرجع!$B$2:$B$19,0)),"") -> التشغيل | I151: OUTF | J151: =IFERROR(INDEX(المرجع!$D$2:$D$19,MATCH($I151,المرجع!$E$2:$E$19,0)),"") -> اكتمال المخرجات المستهدفة | K151: OPERATE-OUTF-1 | L151: =IFERROR(INDEX('نقاط التحقق'!$G$2:$G$31,MATCH($K151,'نقاط التحقق'!$A$2:$A$31,0))&"","") -> اكتمال مخرجات النموذج التشغيلي المستهدف للوحدة التنظيمية | M151: 49 | N151: 80 | O151: =IF($M151="","غير مقيّمة",IF($M151>المرجع!$K$3,"مستوفاة بشكل متقدم",IF($M151<=المرجع!$K$2,"مستوفاة بشكل أولي","مستوفاة بشكل جزئي"))) -> مستوفاة بشكل جزئي | P151: الملاحظات فيذا

Sheet الشؤون التنفيذية
A1: معرف الصف | B1: كود الوحدة | C1: كود المجموعة | D1: القطاع | E1: الوحدة التنظيمية الرئيسية | F1: الوحدة التنظيمية الفرعية | G1: كود المرحلة | H1: المرحلة | I1: كود العنصر | J1: العنصر | K1: كود النقطة | L1: نص نقطة التحقق | M1: الجهة المزودة للمعلومة | N1: نسبة إنجاز النقطة % | O1: نسبة إنجاز النقطة المستهدفة لعام 2026 % | P1: حالة النقطة | Q1: ملاحظات النقطة
A2: EXE-01-DESIGN-ROLE-1 | B2: EXE-01 | C2: =IFERROR(INDEX('قائمة الوحدات'!$B$2:$B$41,MATCH($B2,'قائمة الوحدات'!$A$2:$A$41,0)),"") -> EXE | D2: =IFERROR(INDEX('قائمة الوحدات'!$C$2:$C$41,MATCH($B2,'قائمة الوحدات'!$A$2:$A$41,0)),"") -> الشؤون التنفيذية | E2: =IFERROR(INDEX('قائمة الوحدات'!$D$2:$D$41,MATCH($B2,'قائمة الوحدات'!$A$2:$A$41,0)),"") -> وكالة الشؤون الفنية | F2: =IFERROR(INDEX('قائمة الوحدات'!$F$2:$F$41,MATCH($B2,'قائمة الوحدات'!$A$2:$A$41,0)),"") -> الإدارة العامة للتخطيط والدراسات | G2: DESIGN | H2: =IFERROR(INDEX(المرجع!$A$2:$A$19,MATCH($G2,المرجع!$B$2:$B$19,0)),"") -> التصميم | I2: ROLE | J2: =IFERROR(INDEX(المرجع!$D$2:$D$19,MATCH($I2,المرجع!$E$2:$E$19,0)),"") -> الدور | K2: DESIGN-ROLE-1 | L2: =IFERROR(INDEX('نقاط التحقق'!$G$2:$G$31,MATCH($K2,'نقاط التحقق'!$A$2:$A$31,0))&"","") -> دور مفصل للوحدة التنظيمية | M2: =IFERROR(INDEX('نقاط التحقق'!$H$2:$H$31,MATCH($K2,'نقاط التحقق'!$A$2:$A$31,0))&"","") | N2: 87 | O2: 87 | P2: =IF($N2="","غير مقيّمة",IF($N2>المرجع!$K$3,"مستوفاة بشكل متقدم",IF($N2<=المرجع!$K$2,"مستوفاة بشكل أولي","مستوفاة بشكل جزئي"))) -> مستوفاة بشكل متقدم
A3: EXE-01-DESIGN-KPI-1 | B3: EXE-01 | C3: =IFERROR(INDEX('قائمة الوحدات'!$B$2:$B$41,MATCH($B3,'قائمة الوحدات'!$A$2:$A$41,0)),"") -> EXE | D3: =IFERROR(INDEX('قائمة الوحدات'!$C$2:$C$41,MATCH($B3,'قائمة الوحدات'!$A$2:$A$41,0)),"") -> الشؤون التنفيذية | E3: =IFERROR(INDEX('قائمة الوحدات'!$D$2:$D$41,MATCH($B3,'قائمة الوحدات'!$A$2:$A$41,0)),"") -> وكالة الشؤون الفنية | F3: =IFERROR(INDEX('قائمة الوحدات'!$F$2:$F$41,MATCH($B3,'قائمة الوحدات'!$A$2:$A$41,0)),"") -> الإدارة العامة للتخطيط والدراسات | G3: DESIGN | H3: =IFERROR(INDEX(المرجع!$A$2:$A$19,MATCH($G3,المرجع!$B$2:$B$19,0)),"") -> التصميم | I3: KPI | J3: =IFERROR(INDEX(المرجع!$D$2:$D$19,MATCH($I3,المرجع!$E$2:$E$19,0)),"") -> الأهداف ومؤشرات الأداء | K3: DESIGN-KPI-1 | L3: =IFERROR(INDEX('نقاط التحقق'!$G$2:$G$31,MATCH($K3,'نقاط التحقق'!$A$2:$A$31,0))&"","") -> أهداف محددة للوحدة التنظيمية وربطها بمؤشرات أداء لقياسها | M3: =IFERROR(INDEX('نقاط التحقق'!$H$2:$H$31,MATCH($K3,'نقاط التحقق'!$A$2:$A$31,0))&"","") | N3: 80 | O3: 100 | P3: =IF($N3="","غير مقيّمة",IF($N3>المرجع!$K$3,"مستوفاة بشكل متقدم",IF($N3<=المرجع!$K$2,"مستوفاة بشكل أولي","مستوفاة بشكل جزئي"))) -> مستوفاة بشكل متقدم
A4: EXE-01-DESIGN-KPI-2 | B4: EXE-01 | C4: =IFERROR(INDEX('قائمة الوحدات'!$B$2:$B$41,MATCH($B4,'قائمة الوحدات'!$A$2:$A$41,0)),"") -> EXE | D4: =IFERROR(INDEX('قائمة الوحدات'!$C$2:$C$41,MATCH($B4,'قائمة الوحدات'!$A$2:$A$41,0)),"") -> الشؤون التنفيذية | E4: =IFERROR(INDEX('قائمة الوحدات'!$D$2:$D$41,MATCH($B4,'قائمة الوحدات'!$A$2:$A$41,0)),"") -> وكالة الشؤون الفنية | F4: =IFERROR(INDEX('قائمة الوحدات'!$F$2:$F$41,MATCH($B4,'قائمة الوحدات'!$A$2:$A$41,0)),"") -> الإدارة العامة للتخطيط والدراسات | G4: DESIGN | H4: =IFERROR(INDEX(المرجع!$A$2:$A$19,MATCH($G4,المرجع!$B$2:$B$19,0)),"") -> التصميم | I4: KPI | J4: =IFERROR(INDEX(المرجع!$D$2:$D$19,MATCH($I4,المرجع!$E$2:$E$19,0)),"") -> الأهداف ومؤشرات الأداء | K4: DESIGN-KPI-2 | L4: =IFERROR(INDEX('نقاط التحقق'!$G$2:$G$31,MATCH($K4,'نقاط التحقق'!$A$2:$A$31,0))&"","") -> مؤشرات أداء الوحدة التنظيمية | M4: =IFERROR(INDEX('نقاط التحقق'!$H$2:$H$31,MATCH($K4,'نقاط التحقق'!$A$2:$A$31,0))&"","") | N4: 85 | O4: 90 | P4: =IF($N4="","غير مقيّمة",IF($N4>المرجع!$K$3,"مستوفاة بشكل متقدم",IF($N4<=المرجع!$K$2,"مستوفاة بشكل أولي","مستوفاة بشكل جزئي"))) -> مستوفاة بشكل متقدم
A5: EXE-01-DESIGN-GOV-1 | B5: EXE-01 | C5: =IFERROR(INDEX('قائمة الوحدات'!$B$2:$B$41,MATCH($B5,'قائمة الوحدات'!$A$2:$A$41,0)),"") -> EXE | D5: =IFERROR(INDEX('قائمة الوحدات'!$C$2:$C$41,MATCH($B5,'قائمة الوحدات'!$A$2:$A$41,0)),"") -> الشؤون التنفيذية | E5: =IFERROR(INDEX('قائمة الوحدات'!$D$2:$D$41,MATCH($B5,'قائمة الوحدات'!$A$2:$A$41,0)),"") -> وكالة الشؤون الفنية | F5: =IFERROR(INDEX('قائمة الوحدات'!$F$2:$F$41,MATCH($B5,'قائمة الوحدات'!$A$2:$A$41,0)),"") -> الإدارة العامة للتخطيط والدراسات | G5: DESIGN | H5: =IFERROR(INDEX(المرجع!$A$2:$A$19,MATCH($G5,المرجع!$B$2:$B$19,0)),"") -> التصميم | I5: GOV | J5: =IFERROR(INDEX(المرجع!$D$2:$D$19,MATCH($I5,المرجع!$E$2:$E$19,0)),"") -> الحوكمة | K5: DESIGN-GOV-1 | L5: =IFERROR(INDEX('نقاط التحقق'!$G$2:$G$31,MATCH($K5,'نقاط التحقق'!$A$2:$A$31,0))&"","") -> تفصيل القرارات ومصفوفة الصلاحيات واللجان ذات العلاقة لاعتماد مخرجات الوحدة التنظيمية | M5: =IFERROR(INDEX('نقاط التحقق'!$H$2:$H$31,MATCH($K5,'نقاط التحقق'!$A$2:$A$31,0))&"","") | N5: 93 | O5: 93 | P5: =IF($N5="","غير مقيّمة",IF($N5>المرجع!$K$3,"مستوفاة بشكل متقدم",IF($N5<=المرجع!$K$2,"مستوفاة بشكل أولي","مستوفاة بشكل جزئي"))) -> مستوفاة بشكل متقدم
A6: EXE-01-DESIGN-ORG-1 | B6: EXE-01 | C6: =IFERROR(INDEX('قائمة الوحدات'!$B$2:$B$41,MATCH($B6,'قائمة الوحدات'!$A$2:$A$41,0)),"") -> EXE | D6: =IFERROR(INDEX('قائمة الوحدات'!$C$2:$C$41,MATCH($B6,'قائمة الوحدات'!$A$2:$A$41,0)),"") -> الشؤون التنفيذية | E6: =IFERROR(INDEX('قائمة الوحدات'!$D$2:$D$41,MATCH($B6,'قائمة الوحدات'!$A$2:$A$41,0)),"") -> وكالة الشؤون الفنية | F6: =IFERROR(INDEX('قائمة الوحدات'!$F$2:$F$41,MATCH($B6,'قائمة الوحدات'!$A$2:$A$41,0)),"") -> الإدارة العامة للتخطيط والدراسات | G6: DESIGN | H6: =IFERROR(INDEX(المرجع!$A$2:$A$19,MATCH($G6,المرجع!$B$2:$B$19,0)),"") -> التصميم | I6: ORG | J6: =IFERROR(INDEX(المرجع!$D$2:$D$19,MATCH($I6,المرجع!$E$2:$E$19,0)),"") -> التنظيم | K6: DESIGN-ORG-1 | L6: =IFERROR(INDEX('نقاط التحقق'!$G$2:$G$31,MATCH($K6,'نقاط التحقق'!$A$2:$A$31,0))&"","") -> تطوير الأدوار والمسؤوليات للوحدة التنظيمية وتفصيل الهيكل التنظيمي | M6: =IFERROR(INDEX('نقاط التحقق'!$H$2:$H$31,MATCH($K6,'نقاط التحقق'!$A$2:$A$31,0))&"","") | N6: 74 | O6: 100 | P6: =IF($N6="","غير مقيّمة",IF($N6>المرجع!$K$3,"مستوفاة بشكل متقدم",IF($N6<=المرجع!$K$2,"مستوفاة بشكل أولي","مستوفاة بشكل جزئي"))) -> مستوفاة بشكل متقدم
A7: EXE-01-DESIGN-RES-1 | B7: EXE-01 | C7: =IFERROR(INDEX('قائمة الوحدات'!$B$2:$B$41,MATCH($B7,'قائمة الوحدات'!$A$2:$A$41,0)),"") -> EXE | D7: =IFERROR(INDEX('قائمة الوحدات'!$C$2:$C$41,MATCH($B7,'قائمة الوحدات'!$A$2:$A$41,0)),"") -> الشؤون التنفيذية | E7: =IFERROR(INDEX('قائمة الوحدات'!$D$2:$D$41,MATCH($B7,'قائمة الوحدات'!$A$2:$A$41,0)),"") -> وكالة الشؤون الفنية | F7: =IFERROR(INDEX('قائمة الوحدات'!$F$2:$F$41,MATCH($B7,'قائمة الوحدات'!$A$2:$A$41,0)),"") -> الإدارة العامة للتخطيط والدراسات | G7: DESIGN | H7: =IFERROR(INDEX(المرجع!$A$2:$A$19,MATCH($G7,المرجع!$B$2:$B$19,0)),"") -> التصميم | I7: RES | J7: =IFERROR(INDEX(المرجع!$D$2:$D$19,MATCH($I7,المرجع!$E$2:$E$19,0)),"") -> الموارد | K7: DESIGN-RES-1 | L7: =IFERROR(INDEX('نقاط التحقق'!$G$2:$G$31,MATCH($K7,'نقاط التحقق'!$A$2:$A$31,0))&"","") -> تفصيل احتياج الموارد البشرية للوحدة التنظيمية | M7: =IFERROR(INDEX('نقاط التحقق'!$H$2:$H$31,MATCH($K7,'نقاط التحقق'!$A$2:$A$31,0))&"","") | N7: 68 | O7: 85 | P7: =IF($N7="","غير مقيّمة",IF($N7>المرجع!$K$3,"مستوفاة بشكل متقدم",IF($N7<=المرجع!$K$2,"مستوفاة بشكل أولي","مستوفاة بشكل جزئي"))) -> مستوفاة بشكل جزئي
A8: EXE-01-DESIGN-PROC-1 | B8: EXE-01 | C8: =IFERROR(INDEX('قائمة الوحدات'!$B$2:$B$41,MATCH($B8,'قائمة الوحدات'!$A$2:$A$41,0)),"") -> EXE | D8: =IFERROR(INDEX('قائمة الوحدات'!$C$2:$C$41,MATCH($B8,'قائمة الوحدات'!$A$2:$A$41,0)),"") -> الشؤون التنفيذية | E8: =IFERROR(INDEX('قائمة الوحدات'!$D$2:$D$41,MATCH($B8,'قائمة الوحدات'!$A$2:$A$41,0)),"") -> وكالة الشؤون الفنية | F8: =IFERROR(INDEX('قائمة الوحدات'!$F$2:$F$41,MATCH($B8,'قائمة الوحدات'!$A$2:$A$41,0)),"") -> الإدارة العامة للتخطيط والدراسات | G8: DESIGN | H8: =IFERROR(INDEX(المرجع!$A$2:$A$19,MATCH($G8,المرجع!$B$2:$B$19,0)),"") -> التصميم | I8: PROC | J8: =IFERROR(INDEX(المرجع!$D$2:$D$19,MATCH($I8,المرجع!$E$2:$E$19,0)),"") -> الإجراءات | K8: DESIGN-PROC-1 | L8: =IFERROR(INDEX('نقاط التحقق'!$G$2:$G$31,MATCH($K8,'نقاط التحقق'!$A$2:$A$31,0))&"","") -> تفصيل المخرجات إلى إجراءات عالية المستوى | M8: =IFERROR(INDEX('نقاط التحقق'!$H$2:$H$31,MATCH($K8,'نقاط التحقق'!$A$2:$A$31,0))&"","") | N8: 91 | O8: 95 | P8: =IF($N8="","غير مقيّمة",IF($N8>المرجع!$K$3,"مستوفاة بشكل متقدم",IF($N8<=المرجع!$K$2,"مستوفاة بشكل أولي","مستوفاة بشكل جزئي"))) -> مستوفاة بشكل متقدم
A9: EXE-01-BUILD-ROLE-1 | B9: EXE-01 | C9: =IFERROR(INDEX('قائمة الوحدات'!$B$2:$B$41,MATCH($B9,'قائمة الوحدات'!$A$2:$A$41,0)),"") -> EXE | D9: =IFERROR(INDEX('قائمة الوحدات'!$C$2:$C$41,MATCH($B9,'قائمة الوحدات'!$A$2:$A$41,0)),"") -> الشؤون التنفيذية | E9: =IFERROR(INDEX('قائمة الوحدات'!$D$2:$D$41,MATCH($B9,'قائمة الوحدات'!$A$2:$A$41,0)),"") -> وكالة الشؤون الفنية | F9: =IFERROR(INDEX('قائمة الوحدات'!$F$2:$F$41,MATCH($B9,'قائمة الوحدات'!$A$2:$A$41,0)),"") -> الإدارة العامة للتخطيط والدراسات | G9: BUILD | H9: =IFERROR(INDEX(المرجع!$A$2:$A$19,MATCH($G9,المرجع!$B$2:$B$19,0)),"") -> البناء المؤسسي | I9: ROLE | J9: =IFERROR(INDEX(المرجع!$D$2:$D$19,MATCH($I9,المرجع!$E$2:$E$19,0)),"") -> الدور | K9: BUILD-ROLE-1 | L9: =IFERROR(INDEX('نقاط التحقق'!$G$2:$G$31,MATCH($K9,'نقاط التحقق'!$A$2:$A$31,0))&"","") -> دور معتمد للوحدة التنظيمية | M9: =IFERROR(INDEX('نقاط التحقق'!$H$2:$H$31,MATCH($K9,'نقاط التحقق'!$A$2:$A$31,0))&"","") | N9: 49 | O9: 95 | P9: =IF($N9="","غير مقيّمة",IF($N9>المرجع!$K$3,"مستوفاة بشكل متقدم",IF($N9<=المرجع!$K$2,"مستوفاة بشكل أولي","مستوفاة بشكل جزئي"))) -> مستوفاة بشكل جزئي
A10: EXE-01-BUILD-KPI-1 | B10: EXE-01 | C10: =IFERROR(INDEX('قائمة الوحدات'!$B$2:$B$41,MATCH($B10,'قائمة الوحدات'!$A$2:$A$41,0)),"") -> EXE | D10: =IFERROR(INDEX('قائمة الوحدات'!$C$2:$C$41,MATCH($B10,'قائمة الوحدات'!$A$2:$A$41,0)),"") -> الشؤون التنفيذية | E10: =IFERROR(INDEX('قائمة الوحدات'!$D$2:$D$41,MATCH($B10,'قائمة الوحدات'!$A$2:$A$41,0)),"") -> وكالة الشؤون الفنية | F10: =IFERROR(INDEX('قائمة الوحدات'!$F$2:$F$41,MATCH($B10,'قائمة الوحدات'!$A$2:$A$41,0)),"") -> الإدارة العامة للتخطيط والدراسات | G10: BUILD | H10: =IFERROR(INDEX(المرجع!$A$2:$A$19,MATCH($G10,المرجع!$B$2:$B$19,0)),"") -> البناء المؤسسي | I10: KPI | J10: =IFERROR(INDEX(المرجع!$D$2:$D$19,MATCH($I10,المرجع!$E$2:$E$19,0)),"") -> الأهداف ومؤشرات الأداء | K10: BUILD-KPI-1 | L10: =IFERROR(INDEX('نقاط التحقق'!$G$2:$G$31,MATCH($K10,'نقاط التحقق'!$A$2:$A$31,0))&"","") -> أهداف تشغيلية معتمدة من صاحب الصلاحية | M10: =IFERROR(INDEX('نقاط التحقق'!$H$2:$H$31,MATCH($K10,'نقاط التحقق'!$A$2:$A$31,0))&"","") | N10: 80 | O10: 100 | P10: =IF($N10="","غير مقيّمة",IF($N10>المرجع!$K$3,"مستوفاة بشكل متقدم",IF($N10<=المرجع!$K$2,"مستوفاة بشكل أولي","مستوفاة بشكل جزئي"))) -> مستوفاة بشكل متقدم
A11: EXE-01-BUILD-KPI-2 | B11: EXE-01 | C11: =IFERROR(INDEX('قائمة الوحدات'!$B$2:$B$41,MATCH($B11,'قائمة الوحدات'!$A$2:$A$41,0)),"") -> EXE | D11: =IFERROR(INDEX('قائمة الوحدات'!$C$2:$C$41,MATCH($B11,'قائمة الوحدات'!$A$2:$A$41,0)),"") -> الشؤون التنفيذية | E11: =IFERROR(INDEX('قائمة الوحدات'!$D$2:$D$41,MATCH($B11,'قائمة الوحدات'!$A$2:$A$41,0)),"") -> وكالة الشؤون الفنية | F11: =IFERROR(INDEX('قائمة الوحدات'!$F$2:$F$41,MATCH($B11,'قائمة الوحدات'!$A$2:$A$41,0)),"") -> الإدارة العامة للتخطيط والدراسات | G11: BUILD | H11: =IFERROR(INDEX(المرجع!$A$2:$A$19,MATCH($G11,المرجع!$B$2:$B$19,0)),"") -> البناء المؤسسي | I11: KPI | J11: =IFERROR(INDEX(المرجع!$D$2:$D$19,MATCH($I11,المرجع!$E$2:$E$19,0)),"") -> الأهداف ومؤشرات الأداء | K11: BUILD-KPI-2 | L11: =IFERROR(INDEX('نقاط التحقق'!$G$2:$G$31,MATCH($K11,'نقاط التحقق'!$A$2:$A$31,0))&"","") -> نشر الأهداف التشغيلية على موظفي الوحدة التنظيمية | M11: =IFERROR(INDEX('نقاط التحقق'!$H$2:$H$31,MATCH($K11,'نقاط التحقق'!$A$2:$A$31,0))&"","") | N11: 60 | O11: 95 | P11: =IF($N11="","غير مقيّمة",IF($N11>المرجع!$K$3,"مستوفاة بشكل متقدم",IF($N11<=المرجع!$K$2,"مستوفاة بشكل أولي","مستوفاة بشكل جزئي"))) -> مستوفاة بشكل جزئي
A12: EXE-01-BUILD-GOV-1 | B12: EXE-01 | C12: =IFERROR(INDEX('قائمة الوحدات'!$B$2:$B$41,MATCH($B12,'قائمة الوحدات'!$A$2:$A$41,0)),"") -> EXE | D12: =IFERROR(INDEX('قائمة الوحدات'!$C$2:$C$41,MATCH($B12,'قائمة الوحدات'!$A$2:$A$41,0)),"") -> الشؤون التنفيذية | E12: =IFERROR(INDEX('قائمة الوحدات'!$D$2:$D$41,MATCH($B12,'قائمة الوحدات'!$A$2:$A$41,0)),"") -> وكالة الشؤون الفنية | F12: =IFERROR(INDEX('قائمة الوحدات'!$F$2:$F$41,MATCH($B12,'قائمة الوحدات'!$A$2:$A$41,0)),"") -> الإدارة العامة للتخطيط والدراسات | G12: BUILD | H12: =IFERROR(INDEX(المرجع!$A$2:$A$19,MATCH($G12,المرجع!$B$2:$B$19,0)),"") -> البناء المؤسسي | I12: GOV | J12: =IFERROR(INDEX(المرجع!$D$2:$D$19,MATCH($I12,المرجع!$E$2:$E$19,0)),"") -> الحوكمة | K12: BUILD-GOV-1 | L12: =IFERROR(INDEX('نقاط التحقق'!$G$2:$G$31,MATCH($K12,'نقاط التحقق'!$A$2:$A$31,0))&"","") -> مصفوفة صلاحيات معتمدة ومعممة على أصحاب المصلحة | M12: =IFERROR(INDEX('نقاط التحقق'!$H$2:$H$31,MATCH($K12,'نقاط التحقق'!$A$2:$A$31,0))&"","") | N12: 90 | O12: 90 | P12: =IF($N12="","غير مقيّمة",IF($N12>المرجع!$K$3,"مستوفاة بشكل متقدم",IF($N12<=المرجع!$K$2,"مستوفاة بشكل أولي","مستوفاة بشكل جزئي"))) -> مستوفاة بشكل متقدم
A13: EXE-01-BUILD-GOV-2 | B13: EXE-01 | C13: =IFERROR(INDEX('قائمة الوحدات'!$B$2:$B$41,MATCH($B13,'قائمة الوحدات'!$A$2:$A$41,0)),"") -> EXE | D13: =IFERROR(INDEX('قائمة الوحدات'!$C$2:$C$41,MATCH($B13,'قائمة الوحدات'!$A$2:$A$41,0)),"") -> الشؤون التنفيذية | E13: =IFERROR(INDEX('قائمة الوحدات'!$D$2:$D$41,MATCH($B13,'قائمة الوحدات'!$A$2:$A$41,0)),"") -> وكالة الشؤون الفنية | F13: =IFERROR(INDEX('قائمة الوحدات'!$F$2:$F$41,MATCH($B13,'قائمة الوحدات'!$A$2:$A$41,0)),"") -> الإدارة العامة للتخطيط والدراسات | G13: BUILD | H13: =IFERROR(INDEX(المرجع!$A$2:$A$19,MATCH($G13,المرجع!$B$2:$B$19,0)),"") -> البناء المؤسسي | I13: GOV | J13: =IFERROR(INDEX(المرجع!$D$2:$D$19,MATCH($I13,المرجع!$E$2:$E$19,0)),"") -> الحوكمة | K13: BUILD-GOV-2 | L13: =IFERROR(INDEX('نقاط التحقق'!$G$2:$G$31,MATCH($K13,'نقاط التحقق'!$A$2:$A$31,0))&"","") -> سياسات معتمدة للتي تملكها الوحدة التنظيمية | M13: =IFERROR(INDEX('نقاط التحقق'!$H$2:$H$31,MATCH($K13,'نقاط التحقق'!$A$2:$A$31,0))&"","") | N13: 80 | O13: 85 | P13: =IF($N13="","غير مقيّمة",IF($N13>المرجع!$K$3,"مستوفاة بشكل متقدم",IF($N13<=المرجع!$K$2,"مستوفاة بشكل أولي","مستوفاة بشكل جزئي"))) -> مستوفاة بشكل متقدم
... A239: EXE-08-OPERATE-RES-1 | B239: EXE-08 | C239: =IFERROR(INDEX('قائمة الوحدات'!$B$2:$B$41,MATCH($B239,'قائمة الوحدات'!$A$2:$A$41,0)),"") -> EXE | D239: =IFERROR(INDEX('قائمة الوحدات'!$C$2:$C$41,MATCH($B239,'قائمة الوحدات'!$A$2:$A$41,0)),"") -> الشؤون التنفيذية | E239: =IFERROR(INDEX('قائمة الوحدات'!$D$2:$D$41,MATCH($B239,'قائمة الوحدات'!$A$2:$A$41,0)),"") -> وكالة الخدمات المساندة | F239: =IFERROR(INDEX('قائمة الوحدات'!$F$2:$F$41,MATCH($B239,'قائمة الوحدات'!$A$2:$A$41,0)),"") -> الإدارة العامة للموارد البشرية | G239: OPERATE | H239: =IFERROR(INDEX(المرجع!$A$2:$A$19,MATCH($G239,المرجع!$B$2:$B$19,0)),"") -> التشغيل | I239: RES | J239: =IFERROR(INDEX(المرجع!$D$2:$D$19,MATCH($I239,المرجع!$E$2:$E$19,0)),"") -> الموارد | K239: OPERATE-RES-1 | L239: =IFERROR(INDEX('نقاط التحقق'!$G$2:$G$31,MATCH($K239,'نقاط التحقق'!$A$2:$A$31,0))&"","") -> موارد مستكملة للحد الأدنى الذي يغطي كافة محاور سلسلة القيمة | M239: =IFERROR(INDEX('نقاط التحقق'!$H$2:$H$31,MATCH($K239,'نقاط التحقق'!$A$2:$A$31,0))&"","") | N239: 50 | O239: 100 | P239: =IF($N239="","غير مقيّمة",IF($N239>المرجع!$K$3,"مستوفاة بشكل متقدم",IF($N239<=المرجع!$K$2,"مستوفاة بشكل أولي","مستوفاة بشكل جزئي"))) -> مستوفاة بشكل جزئي
A240: EXE-08-OPERATE-PROC-1 | B240: EXE-08 | C240: =IFERROR(INDEX('قائمة الوحدات'!$B$2:$B$41,MATCH($B240,'قائمة الوحدات'!$A$2:$A$41,0)),"") -> EXE | D240: =IFERROR(INDEX('قائمة الوحدات'!$C$2:$C$41,MATCH($B240,'قائمة الوحدات'!$A$2:$A$41,0)),"") -> الشؤون التنفيذية | E240: =IFERROR(INDEX('قائمة الوحدات'!$D$2:$D$41,MATCH($B240,'قائمة الوحدات'!$A$2:$A$41,0)),"") -> وكالة الخدمات المساندة | F240: =IFERROR(INDEX('قائمة الوحدات'!$F$2:$F$41,MATCH($B240,'قائمة الوحدات'!$A$2:$A$41,0)),"") -> الإدارة العامة للموارد البشرية | G240: OPERATE | H240: =IFERROR(INDEX(المرجع!$A$2:$A$19,MATCH($G240,المرجع!$B$2:$B$19,0)),"") -> التشغيل | I240: PROC | J240: =IFERROR(INDEX(المرجع!$D$2:$D$19,MATCH($I240,المرجع!$E$2:$E$19,0)),"") -> الإجراءات | K240: OPERATE-PROC-1 | L240: =IFERROR(INDEX('نقاط التحقق'!$G$2:$G$31,MATCH($K240,'نقاط التحقق'!$A$2:$A$31,0))&"","") -> تحقيق تقييم "مطبق بشكل كامل" من منهجية تقييم فعالية الإجراءات | M240: =IFERROR(INDEX('نقاط التحقق'!$H$2:$H$31,MATCH($K240,'نقاط التحقق'!$A$2:$A$31,0))&"","") | N240: 60 | O240: 100 | P240: =IF($N240="","غير مقيّمة",IF($N240>المرجع!$K$3,"مستوفاة بشكل متقدم",IF($N240<=المرجع!$K$2,"مستوفاة بشكل أولي","مستوفاة بشكل جزئي"))) -> مستوفاة بشكل جزئي | Q240: الملاحظات فييذا
A241: EXE-08-OPERATE-OUTF-1 | B241: EXE-08 | C241: =IFERROR(INDEX('قائمة الوحدات'!$B$2:$B$41,MATCH($B241,'قائمة الوحدات'!$A$2:$A$41,0)),"") -> EXE | D241: =IFERROR(INDEX('قائمة الوحدات'!$C$2:$C$41,MATCH($B241,'قائمة الوحدات'!$A$2:$A$41,0)),"") -> الشؤون التنفيذية | E241: =IFERROR(INDEX('قائمة الوحدات'!$D$2:$D$41,MATCH($B241,'قائمة الوحدات'!$A$2:$A$41,0)),"") -> وكالة الخدمات المساندة | F241: =IFERROR(INDEX('قائمة الوحدات'!$F$2:$F$41,MATCH($B241,'قائمة الوحدات'!$A$2:$A$41,0)),"") -> الإدارة العامة للموارد البشرية | G241: OPERATE | H241: =IFERROR(INDEX(المرجع!$A$2:$A$19,MATCH($G241,المرجع!$B$2:$B$19,0)),"") -> التشغيل | I241: OUTF | J241: =IFERROR(INDEX(المرجع!$D$2:$D$19,MATCH($I241,المرجع!$E$2:$E$19,0)),"") -> اكتمال المخرجات المستهدفة | K241: OPERATE-OUTF-1 | L241: =IFERROR(INDEX('نقاط التحقق'!$G$2:$G$31,MATCH($K241,'نقاط التحقق'!$A$2:$A$31,0))&"","") -> اكتمال مخرجات النموذج التشغيلي المستهدف للوحدة التنظيمية | M241: =IFERROR(INDEX('نقاط التحقق'!$H$2:$H$31,MATCH($K241,'نقاط التحقق'!$A$2:$A$31,0))&"","") | N241: 31 | O241: 85 | P241: =IF($N241="","غير مقيّمة",IF($N241>المرجع!$K$3,"مستوفاة بشكل متقدم",IF($N241<=المرجع!$K$2,"مستوفاة بشكل أولي","مستوفاة بشكل جزئي"))) -> مستوفاة بشكل جزئي | Q241: الملاحظات فييذا
A242: EXE-09-DESIGN-ROLE-1 | B242: EXE-09 | C242: =IFERROR(INDEX('قائمة الوحدات'!$B$2:$B$41,MATCH($B242,'قائمة الوحدات'!$A$2:$A$41,0)),"") -> EXE | D242: =IFERROR(INDEX('قائمة الوحدات'!$C$2:$C$41,MATCH($B242,'قائمة الوحدات'!$A$2:$A$41,0)),"") -> الشؤون التنفيذية | E242: =IFERROR(INDEX('قائمة الوحدات'!$D$2:$D$41,MATCH($B242,'قائمة الوحدات'!$A$2:$A$41,0)),"") -> وكالة الخدمات المساندة | F242: =IFERROR(INDEX('قائمة الوحدات'!$F$2:$F$41,MATCH($B242,'قائمة الوحدات'!$A$2:$A$41,0)),"") -> الإدارة العامة للشؤون المالية | G242: DESIGN | H242: =IFERROR(INDEX(المرجع!$A$2:$A$19,MATCH($G242,المرجع!$B$2:$B$19,0)),"") -> التصميم | I242: ROLE | J242: =IFERROR(INDEX(المرجع!$D$2:$D$19,MATCH($I242,المرجع!$E$2:$E$19,0)),"") -> الدور | K242: DESIGN-ROLE-1 | L242: =IFERROR(INDEX('نقاط التحقق'!$G$2:$G$31,MATCH($K242,'نقاط التحقق'!$A$2:$A$31,0))&"","") -> دور مفصل للوحدة التنظيمية | M242: =IFERROR(INDEX('نقاط التحقق'!$H$2:$H$31,MATCH($K242,'نقاط التحقق'!$A$2:$A$31,0))&"","") | N242: 70 | O242: 100 | P242: =IF($N242="","غير مقيّمة",IF($N242>المرجع!$K$3,"مستوفاة بشكل متقدم",IF($N242<=المرجع!$K$2,"مستوفاة بشكل أولي","مستوفاة بشكل جزئي"))) -> مستوفاة بشكل جزئي | Q242: الملاحظات فييذا
A243: EXE-09-DESIGN-KPI-1 | B243: EXE-09 | C243: =IFERROR(INDEX('قائمة الوحدات'!$B$2:$B$41,MATCH($B243,'قائمة الوحدات'!$A$2:$A$41,0)),"") -> EXE | D243: =IFERROR(INDEX('قائمة الوحدات'!$C$2:$C$41,MATCH($B243,'قائمة الوحدات'!$A$2:$A$41,0)),"") -> الشؤون التنفيذية | E243: =IFERROR(INDEX('قائمة الوحدات'!$D$2:$D$41,MATCH($B243,'قائمة الوحدات'!$A$2:$A$41,0)),"") -> وكالة الخدمات المساندة | F243: =IFERROR(INDEX('قائمة الوحدات'!$F$2:$F$41,MATCH($B243,'قائمة الوحدات'!$A$2:$A$41,0)),"") -> الإدارة العامة للشؤون المالية | G243: DESIGN | H243: =IFERROR(INDEX(المرجع!$A$2:$A$19,MATCH($G243,المرجع!$B$2:$B$19,0)),"") -> التصميم | I243: KPI | J243: =IFERROR(INDEX(المرجع!$D$2:$D$19,MATCH($I243,المرجع!$E$2:$E$19,0)),"") -> الأهداف ومؤشرات الأداء | K243: DESIGN-KPI-1 | L243: =IFERROR(INDEX('نقاط التحقق'!$G$2:$G$31,MATCH($K243,'نقاط التحقق'!$A$2:$A$31,0))&"","") -> أهداف محددة للوحدة التنظيمية وربطها بمؤشرات أداء لقياسها | M243: =IFERROR(INDEX('نقاط التحقق'!$H$2:$H$31,MATCH($K243,'نقاط التحقق'!$A$2:$A$31,0))&"","") | N243: 95 | O243: 100 | P243: =IF($N243="","غير مقيّمة",IF($N243>المرجع!$K$3,"مستوفاة بشكل متقدم",IF($N243<=المرجع!$K$2,"مستوفاة بشكل أولي","مستوفاة بشكل جزئي"))) -> مستوفاة بشكل متقدم | Q243: الملاحظات فييذا
A244: EXE-09-DESIGN-KPI-2 | B244: EXE-09 | C244: =IFERROR(INDEX('قائمة الوحدات'!$B$2:$B$41,MATCH($B244,'قائمة الوحدات'!$A$2:$A$41,0)),"") -> EXE | D244: =IFERROR(INDEX('قائمة الوحدات'!$C$2:$C$41,MATCH($B244,'قائمة الوحدات'!$A$2:$A$41,0)),"") -> الشؤون التنفيذية | E244: =IFERROR(INDEX('قائمة الوحدات'!$D$2:$D$41,MATCH($B244,'قائمة الوحدات'!$A$2:$A$41,0)),"") -> وكالة الخدمات المساندة | F244: =IFERROR(INDEX('قائمة الوحدات'!$F$2:$F$41,MATCH($B244,'قائمة الوحدات'!$A$2:$A$41,0)),"") -> الإدارة العامة للشؤون المالية | G244: DESIGN | H244: =IFERROR(INDEX(المرجع!$A$2:$A$19,MATCH($G244,المرجع!$B$2:$B$19,0)),"") -> التصميم | I244: KPI | J244: =IFERROR(INDEX(المرجع!$D$2:$D$19,MATCH($I244,المرجع!$E$2:$E$19,0)),"") -> الأهداف ومؤشرات الأداء | K244: DESIGN-KPI-2 | L244: =IFERROR(INDEX('نقاط التحقق'!$G$2:$G$31,MATCH($K244,'نقاط التحقق'!$A$2:$A$31,0))&"","") -> مؤشرات أداء الوحدة التنظيمية | M244: =IFERROR(INDEX('نقاط التحقق'!$H$2:$H$31,MATCH($K244,'نقاط التحقق'!$A$2:$A$31,0))&"","") | N244: 70 | O244: 100 | P244: =IF($N244="","غير مقيّمة",IF($N244>المرجع!$K$3,"مستوفاة بشكل متقدم",IF($N244<=المرجع!$K$2,"مستوفاة بشكل أولي","مستوفاة بشكل جزئي"))) -> مستوفاة بشكل جزئي | Q244: الملاحظات فييذا
A245: EXE-09-DESIGN-GOV-1 | B245: EXE-09 | C245: =IFERROR(INDEX('قائمة الوحدات'!$B$2:$B$41,MATCH($B245,'قائمة الوحدات'!$A$2:$A$41,0)),"") -> EXE | D245: =IFERROR(INDEX('قائمة الوحدات'!$C$2:$C$41,MATCH($B245,'قائمة الوحدات'!$A$2:$A$41,0)),"") -> الشؤون التنفيذية | E245: =IFERROR(INDEX('قائمة الوحدات'!$D$2:$D$41,MATCH($B245,'قائمة الوحدات'!$A$2:$A$41,0)),"") -> وكالة الخدمات المساندة | F245: =IFERROR(INDEX('قائمة الوحدات'!$F$2:$F$41,MATCH($B245,'قائمة الوحدات'!$A$2:$A$41,0)),"") -> الإدارة العامة للشؤون المالية | G245: DESIGN | H245: =IFERROR(INDEX(المرجع!$A$2:$A$19,MATCH($G245,المرجع!$B$2:$B$19,0)),"") -> التصميم | I245: GOV | J245: =IFERROR(INDEX(المرجع!$D$2:$D$19,MATCH($I245,المرجع!$E$2:$E$19,0)),"") -> الحوكمة | K245: DESIGN-GOV-1 | L245: =IFERROR(INDEX('نقاط التحقق'!$G$2:$G$31,MATCH($K245,'نقاط التحقق'!$A$2:$A$31,0))&"","") -> تفصيل القرارات ومصفوفة الصلاحيات واللجان ذات العلاقة لاعتماد مخرجات الوحدة التنظيمية | M245: =IFERROR(INDEX('نقاط التحقق'!$H$2:$H$31,MATCH($K245,'نقاط التحقق'!$A$2:$A$31,0))&"","") | N245: 71 | O245: 95 | P245: =IF($N245="","غير مقيّمة",IF($N245>المرجع!$K$3,"مستوفاة بشكل متقدم",IF($N245<=المرجع!$K$2,"مستوفاة بشكل أولي","مستوفاة بشكل جزئي"))) -> مستوفاة بشكل متقدم | Q245: الملاحظات فييذا
A246: EXE-09-DESIGN-ORG-1 | B246: EXE-09 | C246: =IFERROR(INDEX('قائمة الوحدات'!$B$2:$B$41,MATCH($B246,'قائمة الوحدات'!$A$2:$A$41,0)),"") -> EXE | D246: =IFERROR(INDEX('قائمة الوحدات'!$C$2:$C$41,MATCH($B246,'قائمة الوحدات'!$A$2:$A$41,0)),"") -> الشؤون التنفيذية | E246: =IFERROR(INDEX('قائمة الوحدات'!$D$2:$D$41,MATCH($B246,'قائمة الوحدات'!$A$2:$A$41,0)),"") -> وكالة الخدمات المساندة | F246: =IFERROR(INDEX('قائمة الوحدات'!$F$2:$F$41,MATCH($B246,'قائمة الوحدات'!$A$2:$A$41,0)),"") -> الإدارة العامة للشؤون المالية | G246: DESIGN | H246: =IFERROR(INDEX(المرجع!$A$2:$A$19,MATCH($G246,المرجع!$B$2:$B$19,0)),"") -> التصميم | I246: ORG | J246: =IFERROR(INDEX(المرجع!$D$2:$D$19,MATCH($I246,المرجع!$E$2:$E$19,0)),"") -> التنظيم | K246: DESIGN-ORG-1 | L246: =IFERROR(INDEX('نقاط التحقق'!$G$2:$G$31,MATCH($K246,'نقاط التحقق'!$A$2:$A$31,0))&"","") -> تطوير الأدوار والمسؤوليات للوحدة التنظيمية وتفصيل الهيكل التنظيمي | M246: =IFERROR(INDEX('نقاط التحقق'!$H$2:$H$31,MATCH($K246,'نقاط التحقق'!$A$2:$A$31,0))&"","") | N246: 80 | O246: 100 | P246: =IF($N246="","غير مقيّمة",IF($N246>المرجع!$K$3,"مستوفاة بشكل متقدم",IF($N246<=المرجع!$K$2,"مستوفاة بشكل أولي","مستوفاة بشكل جزئي"))) -> مستوفاة بشكل متقدم | Q246: الملاحظات فييذا
A247: EXE-09-DESIGN-RES-1 | B247: EXE-09 | C247: =IFERROR(INDEX('قائمة الوحدات'!$B$2:$B$41,MATCH($B247,'قائمة الوحدات'!$A$2:$A$41,0)),"") -> EXE | D247: =IFERROR(INDEX('قائمة الوحدات'!$C$2:$C$41,MATCH($B247,'قائمة الوحدات'!$A$2:$A$41,0)),"") -> الشؤون التنفيذية | E247: =IFERROR(INDEX('قائمة الوحدات'!$D$2:$D$41,MATCH($B247,'قائمة الوحدات'!$A$2:$A$41,0)),"") -> وكالة الخدمات المساندة | F247: =IFERROR(INDEX('قائمة الوحدات'!$F$2:$F$41,MATCH($B247,'قائمة الوحدات'!$A$2:$A$41,0)),"") -> الإدارة العامة للشؤون المالية | G247: DESIGN | H247: =IFERROR(INDEX(المرجع!$A$2:$A$19,MATCH($G247,المرجع!$B$2:$B$19,0)),"") -> التصميم | I247: RES | J247: =IFERROR(INDEX(المرجع!$D$2:$D$19,MATCH($I247,المرجع!$E$2:$E$19,0)),"") -> الموارد | K247: DESIGN-RES-1 | L247: =IFERROR(INDEX('نقاط التحقق'!$G$2:$G$31,MATCH($K247,'نقاط التحقق'!$A$2:$A$31,0))&"","") -> تفصيل احتياج الموارد البشرية للوحدة التنظيمية | M247: =IFERROR(INDEX('نقاط التحقق'!$H$2:$H$31,MATCH($K247,'نقاط التحقق'!$A$2:$A$31,0))&"","") | N247: 89 | O247: 90 | P247: =IF($N247="","غير مقيّمة",IF($N247>المرجع!$K$3,"مستوفاة بشكل متقدم",IF($N247<=المرجع!$K$2,"مستوفاة بشكل أولي","مستوفاة بشكل جزئي"))) -> مستوفاة بشكل متقدم | Q247: الملاحظات فييذا
A248: EXE-09-DESIGN-PROC-1 | B248: EXE-09 | C248: =IFERROR(INDEX('قائمة الوحدات'!$B$2:$B$41,MATCH($B248,'قائمة الوحدات'!$A$2:$A$41,0)),"") -> EXE | D248: =IFERROR(INDEX('قائمة الوحدات'!$C$2:$C$41,MATCH($B248,'قائمة الوحدات'!$A$2:$A$41,0)),"") -> الشؤون التنفيذية | E248: =IFERROR(INDEX('قائمة الوحدات'!$D$2:$D$41,MATCH($B248,'قائمة الوحدات'!$A$2:$A$41,0)),"") -> وكالة الخدمات المساندة | F248: =IFERROR(INDEX('قائمة الوحدات'!$F$2:$F$41,MATCH($B248,'قائمة الوحدات'!$A$2:$A$41,0)),"") -> الإدارة العامة للشؤون المالية | G248: DESIGN | H248: =IFERROR(INDEX(المرجع!$A$2:$A$19,MATCH($G248,المرجع!$B$2:$B$19,0)),"") -> التصميم | I248: PROC | J248: =IFERROR(INDEX(المرجع!$D$2:$D$19,MATCH($I248,المرجع!$E$2:$E$19,0)),"") -> الإجراءات | K248: DESIGN-PROC-1 | L248: =IFERROR(INDEX('نقاط التحقق'!$G$2:$G$31,MATCH($K248,'نقاط التحقق'!$A$2:$A$31,0))&"","") -> تفصيل المخرجات إلى إجراءات عالية المستوى | M248: =IFERROR(INDEX('نقاط التحقق'!$H$2:$H$31,MATCH($K248,'نقاط التحقق'!$A$2:$A$31,0))&"","") | N248: 81 | O248: 85 | P248: =IF($N248="","غير مقيّمة",IF($N248>المرجع!$K$3,"مستوفاة بشكل متقدم",IF($N248<=المرجع!$K$2,"مستوفاة بشكل أولي","مستوفاة بشكل جزئي"))) -> مستوفاة بشكل متقدم | Q248: الملاحظات فييذا
A249: EXE-09-BUILD-ROLE-1 | B249: EXE-09 | C249: =IFERROR(INDEX('قائمة الوحدات'!$B$2:$B$41,MATCH($B249,'قائمة الوحدات'!$A$2:$A$41,0)),"") -> EXE | D249: =IFERROR(INDEX('قائمة الوحدات'!$C$2:$C$41,MATCH($B249,'قائمة الوحدات'!$A$2:$A$41,0)),"") -> الشؤون التنفيذية | E249: =IFERROR(INDEX('قائمة الوحدات'!$D$2:$D$41,MATCH($B249,'قائمة الوحدات'!$A$2:$A$41,0)),"") -> وكالة الخدمات المساندة | F249: =IFERROR(INDEX('قائمة الوحدات'!$F$2:$F$41,MATCH($B249,'قائمة الوحدات'!$A$2:$A$41,0)),"") -> الإدارة العامة للشؤون المالية | G249: BUILD | H249: =IFERROR(INDEX(المرجع!$A$2:$A$19,MATCH($G249,المرجع!$B$2:$B$19,0)),"") -> البناء المؤسسي | I249: ROLE | J249: =IFERROR(INDEX(المرجع!$D$2:$D$19,MATCH($I249,المرجع!$E$2:$E$19,0)),"") -> الدور | K249: BUILD-ROLE-1 | L249: =IFERROR(INDEX('نقاط التحقق'!$G$2:$G$31,MATCH($K249,'نقاط التحقق'!$A$2:$A$31,0))&"","") -> دور معتمد للوحدة التنظيمية | M249: =IFERROR(INDEX('نقاط التحقق'!$H$2:$H$31,MATCH($K249,'نقاط التحقق'!$A$2:$A$31,0))&"","") | N249: 53 | O249: 100 | P249: =IF($N249="","غير مقيّمة",IF($N249>المرجع!$K$3,"مستوفاة بشكل متقدم",IF($N249<=المرجع!$K$2,"مستوفاة بشكل أولي","مستوفاة بشكل جزئي"))) -> مستوفاة بشكل جزئي | Q249: الملاحظات فييذا
A250: EXE-09-BUILD-KPI-1 | B250: EXE-09 | C250: =IFERROR(INDEX('قائمة الوحدات'!$B$2:$B$41,MATCH($B250,'قائمة الوحدات'!$A$2:$A$41,0)),"") -> EXE | D250: =IFERROR(INDEX('قائمة الوحدات'!$C$2:$C$41,MATCH($B250,'قائمة الوحدات'!$A$2:$A$41,0)),"") -> الشؤون التنفيذية | E250: =IFERROR(INDEX('قائمة الوحدات'!$D$2:$D$41,MATCH($B250,'قائمة الوحدات'!$A$2:$A$41,0)),"") -> وكالة الخدمات المساندة | F250: =IFERROR(INDEX('قائمة الوحدات'!$F$2:$F$41,MATCH($B250,'قائمة الوحدات'!$A$2:$A$41,0)),"") -> الإدارة العامة للشؤون المالية | G250: BUILD | H250: =IFERROR(INDEX(المرجع!$A$2:$A$19,MATCH($G250,المرجع!$B$2:$B$19,0)),"") -> البناء المؤسسي | I250: KPI | J250: =IFERROR(INDEX(المرجع!$D$2:$D$19,MATCH($I250,المرجع!$E$2:$E$19,0)),"") -> الأهداف ومؤشرات الأداء | K250: BUILD-KPI-1 | L250: =IFERROR(INDEX('نقاط التحقق'!$G$2:$G$31,MATCH($K250,'نقاط التحقق'!$A$2:$A$31,0))&"","") -> أهداف تشغيلية معتمدة من صاحب الصلاحية | M250: =IFERROR(INDEX('نقاط التحقق'!$H$2:$H$31,MATCH($K250,'نقاط التحقق'!$A$2:$A$31,0))&"","") | N250: 90 | O250: 100 | P250: =IF($N250="","غير مقيّمة",IF($N250>المرجع!$K$3,"مستوفاة بشكل متقدم",IF($N250<=المرجع!$K$2,"مستوفاة بشكل أولي","مستوفاة بشكل جزئي"))) -> مستوفاة بشكل متقدم | Q250: الملاحظات فييذا
A251: EXE-09-BUILD-KPI-2 | B251: EXE-09 | C251: =IFERROR(INDEX('قائمة الوحدات'!$B$2:$B$41,MATCH($B251,'قائمة الوحدات'!$A$2:$A$41,0)),"") -> EXE | D251: =IFERROR(INDEX('قائمة الوحدات'!$C$2:$C$41,MATCH($B251,'قائمة الوحدات'!$A$2:$A$41,0)),"") -> الشؤون التنفيذية | E251: =IFERROR(INDEX('قائمة الوحدات'!$D$2:$D$41,MATCH($B251,'قائمة الوحدات'!$A$2:$A$41,0)),"") -> وكالة الخدمات المساندة | F251: =IFERROR(INDEX('قائمة الوحدات'!$F$2:$F$41,MATCH($B251,'قائمة الوحدات'!$A$2:$A$41,0)),"") -> الإدارة العامة للشؤون المالية | G251: BUILD | H251: =IFERROR(INDEX(المرجع!$A$2:$A$19,MATCH($G251,المرجع!$B$2:$B$19,0)),"") -> البناء المؤسسي | I251: KPI | J251: =IFERROR(INDEX(المرجع!$D$2:$D$19,MATCH($I251,المرجع!$E$2:$E$19,0)),"") -> الأهداف ومؤشرات الأداء | K251: BUILD-KPI-2 | L251: =IFERROR(INDEX('نقاط التحقق'!$G$2:$G$31,MATCH($K251,'نقاط التحقق'!$A$2:$A$31,0))&"","") -> نشر الأهداف التشغيلية على موظفي الوحدة التنظيمية | M251: =IFERROR(INDEX('نقاط التحقق'!$H$2:$H$31,MATCH($K251,'نقاط التحقق'!$A$2:$A$31,0))&"","") | N251: 75 | O251: 85 | P251: =IF($N251="","غير مقيّمة",IF($N251>المرجع!$K$3,"مستوفاة بشكل متقدم",IF($N251<=المرجع!$K$2,"مستوفاة بشكل أولي","مستوفاة بشكل جزئي"))) -> مستوفاة بشكل متقدم | Q251: الملاحظات فييذا
... A421: EXE-14-OPERATE-OUTF-1 | B421: EXE-14 | C421: =IFERROR(INDEX('قائمة الوحدات'!$B$2:$B$41,MATCH($B421,'قائمة الوحدات'!$A$2:$A$41,0)),"") -> EXE | D421: =IFERROR(INDEX('قائمة الوحدات'!$C$2:$C$41,MATCH($B421,'قائمة الوحدات'!$A$2:$A$41,0)),"") -> الشؤون التنفيذية | E421: =IFERROR(INDEX('قائمة الوحدات'!$D$2:$D$41,MATCH($B421,'قائمة الوحدات'!$A$2:$A$41,0)),"") -> وكالة الرقابة والالتزام | F421: =IFERROR(INDEX('قائمة الوحدات'!$F$2:$F$41,MATCH($B421,'قائمة الوحدات'!$A$2:$A$41,0)),"") -> وكالة الرقابة والالتزام | G421: OPERATE | H421: =IFERROR(INDEX(المرجع!$A$2:$A$19,MATCH($G421,المرجع!$B$2:$B$19,0)),"") -> التشغيل | I421: OUTF | J421: =IFERROR(INDEX(المرجع!$D$2:$D$19,MATCH($I421,المرجع!$E$2:$E$19,0)),"") -> اكتمال المخرجات المستهدفة | K421: OPERATE-OUTF-1 | L421: =IFERROR(INDEX('نقاط التحقق'!$G$2:$G$31,MATCH($K421,'نقاط التحقق'!$A$2:$A$31,0))&"","") -> اكتمال مخرجات النموذج التشغيلي المستهدف للوحدة التنظيمية | M421: =IFERROR(INDEX('نقاط التحقق'!$H$2:$H$31,MATCH($K421,'نقاط التحقق'!$A$2:$A$31,0))&"","") | N421: 56 | O421: 100 | P421: =IF($N421="","غير مقيّمة",IF($N421>المرجع!$K$3,"مستوفاة بشكل متقدم",IF($N421<=المرجع!$K$2,"مستوفاة بشكل أولي","مستوفاة بشكل جزئي"))) -> مستوفاة بشكل جزئي | Q421: الملاحظات فييذا

Sheet الجهاز العسكري
A1: معرف الصف | B1: كود الوحدة | C1: كود المجموعة | D1: القطاع | E1: الوحدة التنظيمية الرئيسية | F1: الوحدة التنظيمية الفرعية | G1: كود المرحلة | H1: المرحلة | I1: كود العنصر | J1: العنصر | K1: كود النقطة | L1: نص نقطة التحقق | M1: نسبة إنجاز النقطة % | N1: نسبة إنجاز النقطة المستهدفة لعام 2026 % | O1: حالة النقطة | P1: ملاحظات النقطة
A2: MIL-01-DESIGN-ROLE-1 | B2: MIL-01 | C2: =IFERROR(INDEX('قائمة الوحدات'!$B$2:$B$41,MATCH($B2,'قائمة الوحدات'!$A$2:$A$41,0)),"") -> MIL | D2: =IFERROR(INDEX('قائمة الوحدات'!$C$2:$C$41,MATCH($B2,'قائمة الوحدات'!$A$2:$A$41,0)),"") -> الجهاز العسكري | E2: =IFERROR(INDEX('قائمة الوحدات'!$D$2:$D$41,MATCH($B2,'قائمة الوحدات'!$A$2:$A$41,0)),"") -> هيئة الأركان | F2: =IFERROR(INDEX('قائمة الوحدات'!$F$2:$F$41,MATCH($B2,'قائمة الوحدات'!$A$2:$A$41,0)),"") -> هيئة الأركان | G2: DESIGN | H2: =IFERROR(INDEX(المرجع!$A$2:$A$19,MATCH($G2,المرجع!$B$2:$B$19,0)),"") -> التصميم | I2: ROLE | J2: =IFERROR(INDEX(المرجع!$D$2:$D$19,MATCH($I2,المرجع!$E$2:$E$19,0)),"") -> الدور | K2: DESIGN-ROLE-1 | L2: =IFERROR(INDEX('نقاط التحقق'!$G$2:$G$31,MATCH($K2,'نقاط التحقق'!$A$2:$A$31,0))&"","") -> دور مفصل للوحدة التنظيمية | M2: 72 | N2: 80 | O2: =IF($M2="","غير مقيّمة",IF($M2>المرجع!$K$3,"مستوفاة بشكل متقدم",IF($M2<=المرجع!$K$2,"مستوفاة بشكل أولي","مستوفاة بشكل جزئي"))) -> مستوفاة بشكل متقدم | P2: الملاحظات فييذا
